Workbook

Sheet Dados Físicos
A1: N_Jogo | B1: Group/Stage | C1: Stage | D1: Date | E1: Local Time | F1: Time_of_day | G1: Stadium | H1: Stadium_type | I1: City | J1: Team | K1: Origin_climate | L1: Team_classification | M1: Team_elimination | N1: Opponent | O1: Opponent_classification | P1: Opponent_elimination | Q1: Ranking_difference | R1: Team_ide | S1: Player_id | T1: Player # | U1: Player | V1: Player_position | W1: Player_age | X1: Entrou | Y1: Saiu | Z1: Duração 1º tempo | AA1: Tempo jogado (1º tempo) | AB1: Duração 2º tempo | AC1: Tempo jogado (2º tempo) | AD1: Duração Prorrogação | AE1: Tempo jogado (prorrogação) | AF1: Played_minutes | AG1: Total Distance (m) | AH1: Zone 1:0-7 km/h (m) | AI1: Zone 2:7-15 km/h (m) | AJ1: Zone 3:15-20 km/h (m) | AK1: Zone 4:20-25 km/h (m) | AL1: Zone 5:25+km/h (m) | AM1: # High Speed Runs (Zone 3) | AN1: # Sprints (Zone 4 & 5) | AO1: Top_Speed | AP1: Total_distance_min | AQ1: Zone1_min | AR1: Zone2_min | AS1: Zone12_min | AT1: Zone3_min | AU1: Zone4_min | AV1: Zone5_min | AW1: Zone45_min | AX1: N_zone3_min | AY1: N_zone4e5_min | AZ1: Temp | BA1: Tdew | BB1: UR | BC1: UA | BD1: RAD | BE1: V | BF1: TN | BG1: TG | BH1: WBGT
A2: 1 | B2: Group A | C2: Group | D2: 45822 | E2: 0.83333333 | F2: =VLOOKUP(A2,Jogos!A:N,10,0) -> Evening | G2: Hard Rock Stadium | H2: =VLOOKUP(A2,Jogos!A:L,12,0) -> Open | I2: =VLOOKUP(G2,'Estádios e Cidades'!A:B,2,0) -> Miami Gardens - Flórida | J2: Al Ahly FC | K2: =VLOOKUP(J2,Equipes!A:F,6,0) -> Tropical | L2: =VLOOKUP(J2,Equipes!A:C,3,0) -> 25 | M2: =if(L2<3,"Final",IF(L2<5,"Semi-final",if(L2<9,"Quarter-final",if(L2<17,"Round of 16","Group")))) -> Group | N2: Inter Miami CF | O2: =VLOOKUP(N2,Equipes!A:C,3,0) -> 16 | P2: =if(O2<3,"Final",IF(O2<5,"Semi-final",if(O2<9,"Quarter-final",if(O2<17,"Round of 16","Group")))) -> Round of 16 | Q2: =L2-O2 -> 9 | R2: =VLOOKUP(J2,Equipes!A:B,2,0) -> AlAhly | S2: 5-AlAhly | T2: 5 | U2: Mohamed Ali BEN ROMDHANE | V2: =VLOOKUP(U2,Jogadores!B:C,2,0) -> MF | W2: =VLOOKUP(U2,Jogadores!B:D,3,0) -> 25.909589 | X2: 0 | Y2: 65 | Z2: =VLOOKUP(A2,Jogos!A:L,3,0) -> 48 | AA2: =IF(X2<45,if(Y2>=45,Z2-X2,if(Y2<=Z2,Y2-X2,Z2)),0) -> 48 | AB2: =VLOOKUP(A2,Jogos!A:L,4,0) -> 53 | AC2: =IF(X2<45,if(Y2<=45,0,Y2-45),AB2+45-X2) -> 20 | AF2: =AE2+AC2+AA2 -> 68 | AG2: 7541.9 | AH2: 2606 | AI2: 3421.8 | AJ2: 961.6 | AK2: 413.3 | AL2: 139.2 | AM2: 81 | AN2: 32 | AO2: 34.6 | AP2: =AG2/$AF2 -> 110.91029 | AQ2: =AH2/$AF2 -> 38.323529 | AR2: =AI2/$AF2 -> 50.320588 | AS2: =AQ2+AR2 -> 88.644118 | AT2: =AJ2/$AF2 -> 14.141176 | AU2: =AK2/$AF2 -> 6.0779412 | AV2: =AL2/$AF2 -> 2.0470588 | AW2: =(AK2+AL2)/AF2 -> 8.125 | AX2: =AM2/$AF2 -> 1.1911765 | AY2: =AN2/$AF2 -> 0.47058824 | AZ2: =VLOOKUP(A2,Jogos!A:BN,58,0) -> 28.26 | BA2: =VLOOKUP(A2,Jogos!A:BN,59,0) -> 22.895 | BB2: =VLOOKUP(A2,Jogos!A:BN,60,0) -> 72 | BC2: =VLOOKUP(A2,Jogos!A:BN,61,0) -> 27.605 | BD2: =VLOOKUP(A2,Jogos!A:BN,62,0) -> 0.5 | BE2: =VLOOKUP(A2,Jogos!A:BN,63,0) -> 2.07 | BF2: =VLOOKUP(A2,Jogos!A:BN,64,0) -> 24.755 | BG2: =VLOOKUP(A2,Jogos!A:BN,65,0) -> 42.805 | BH2: =VLOOKUP(A2,Jogos!A:BN,66,0) -> 28.715
A3: 1 | B3: Group A | C3: Group | D3: 45822 | E3: 0.83333333 | F3: =VLOOKUP(A3,Jogos!A:N,10,0) -> Evening | G3: Hard Rock Stadium | H3: =VLOOKUP(A3,Jogos!A:L,12,0) -> Open | I3: =VLOOKUP(G3,'Estádios e Cidades'!A:B,2,0) -> Miami Gardens - Flórida | J3: Al Ahly FC | K3: =VLOOKUP(J3,Equipes!A:F,6,0) -> Tropical | L3: =VLOOKUP(J3,Equipes!A:C,3,0) -> 25 | M3: =if(L3<3,"Final",IF(L3<5,"Semi-final",if(L3<9,"Quarter-final",if(L3<17,"Round of 16","Group")))) -> Group | N3: Inter Miami CF | O3: =VLOOKUP(N3,Equipes!A:C,3,0) -> 16 | P3: =if(O3<3,"Final",IF(O3<5,"Semi-final",if(O3<9,"Quarter-final",if(O3<17,"Round of 16","Group")))) -> Round of 16 | Q3: =L3-O3 -> 9 | R3: =VLOOKUP(J3,Equipes!A:B,2,0) -> AlAhly | S3: 6-AlAhly | T3: 6 | U3: YASSER IBRAHIM | V3: =VLOOKUP(U3,Jogadores!B:C,2,0) -> DF | W3: =VLOOKUP(U3,Jogadores!B:D,3,0) -> 32.482192 | X3: 0 | Y3: =45+AB3 -> 98 | Z3: =VLOOKUP(A3,Jogos!A:L,3,0) -> 48 | AA3: =IF(X3<45,if(Y3>=45,Z3-X3,if(Y3<=Z3,Y3-X3,Z3)),0) -> 48 | AB3: =VLOOKUP(A3,Jogos!A:L,4,0) -> 53 | AC3: =IF(X3<45,if(Y3<=45,0,Y3-45),AB3+45-X3) -> 53 | AF3: =AE3+AC3+AA3 -> 101 | AG3: 9231.5 | AH3: 4069.6 | AI3: 3477.4 | AJ3: 1076.8 | AK3: 480.2 | AL3: 127.5 | AM3: 90 | AN3: 43 | AO3: 28.9 | AP3: =AG3/$AF3 -> 91.40099 | AQ3: =AH3/$AF3 -> 40.293069 | AR3: =AI3/$AF3 -> 34.429703 | AS3: =AQ3+AR3 -> 74.722772 | AT3: =AJ3/$AF3 -> 10.661386 | AU3: =AK3/$AF3 -> 4.7544554 | AV3: =AL3/$AF3 -> 1.2623762 | AW3: =(AK3+AL3)/AF3 -> 6.0168317 | AX3: =AM3/$AF3 -> 0.89108911 | AY3: =AN3/$AF3 -> 0.42574257 | AZ3: =VLOOKUP(A3,Jogos!A:BN,58,0) -> 28.26 | BA3: =VLOOKUP(A3,Jogos!A:BN,59,0) -> 22.895 | BB3: =VLOOKUP(A3,Jogos!A:BN,60,0) -> 72 | BC3: =VLOOKUP(A3,Jogos!A:BN,61,0) -> 27.605 | BD3: =VLOOKUP(A3,Jogos!A:BN,62,0) -> 0.5 | BE3: =VLOOKUP(A3,Jogos!A:BN,63,0) -> 2.07 | BF3: =VLOOKUP(A3,Jogos!A:BN,64,0) -> 24.755 | BG3: =VLOOKUP(A3,Jogos!A:BN,65,0) -> 42.805 | BH3: =VLOOKUP(A3,Jogos!A:BN,66,0) -> 28.715
A4: 1 | B4: Group A | C4: Group | D4: 45822 | E4: 0.83333333 | F4: =VLOOKUP(A4,Jogos!A:N,10,0) -> Evening | G4: Hard Rock Stadium | H4: =VLOOKUP(A4,Jogos!A:L,12,0) -> Open | I4: =VLOOKUP(G4,'Estádios e Cidades'!A:B,2,0) -> Miami Gardens - Flórida | J4: Al Ahly FC | K4: =VLOOKUP(J4,Equipes!A:F,6,0) -> Tropical | L4: =VLOOKUP(J4,Equipes!A:C,3,0) -> 25 | M4: =if(L4<3,"Final",IF(L4<5,"Semi-final",if(L4<9,"Quarter-final",if(L4<17,"Round of 16","Group")))) -> Group | N4: Inter Miami CF | O4: =VLOOKUP(N4,Equipes!A:C,3,0) -> 16 | P4: =if(O4<3,"Final",IF(O4<5,"Semi-final",if(O4<9,"Quarter-final",if(O4<17,"Round of 16","Group")))) -> Round of 16 | Q4: =L4-O4 -> 9 | R4: =VLOOKUP(J4,Equipes!A:B,2,0) -> AlAhly | S4: 7-AlAhly | T4: 7 | U4: TREZEGUET | V4: =VLOOKUP(U4,Jogadores!B:C,2,0) -> MF | W4: =VLOOKUP(U4,Jogadores!B:D,3,0) -> 30.843836 | X4: 0 | Y4: 65 | Z4: =VLOOKUP(A4,Jogos!A:L,3,0) -> 48 | AA4: =IF(X4<45,if(Y4>=45,Z4-X4,if(Y4<=Z4,Y4-X4,Z4)),0) -> 48 | AB4: =VLOOKUP(A4,Jogos!A:L,4,0) -> 53 | AC4: =IF(X4<45,if(Y4<=45,0,Y4-45),AB4+45-X4) -> 20 | AF4: =AE4+AC4+AA4 -> 68 | AG4: 7088.6 | AH4: 3075.2 | AI4: 2362 | AJ4: 917.8 | AK4: 451.3 | AL4: 282.4 | AM4: 87 | AN4: 43 | AO4: 35.4 | AP4: =AG4/$AF4 -> 104.24412 | AQ4: =AH4/$AF4 -> 45.223529 | AR4: =AI4/$AF4 -> 34.735294 | AS4: =AQ4+AR4 -> 79.958824 | AT4: =AJ4/$AF4 -> 13.497059 | AU4: =AK4/$AF4 -> 6.6367647 | AV4: =AL4/$AF4 -> 4.1529412 | AW4: =(AK4+AL4)/AF4 -> 10.789706 | AX4: =AM4/$AF4 -> 1.2794118 | AY4: =AN4/$AF4 -> 0.63235294 | AZ4: =VLOOKUP(A4,Jogos!A:BN,58,0) -> 28.26 | BA4: =VLOOKUP(A4,Jogos!A:BN,59,0) -> 22.895 | BB4: =VLOOKUP(A4,Jogos!A:BN,60,0) -> 72 | BC4: =VLOOKUP(A4,Jogos!A:BN,61,0) -> 27.605 | BD4: =VLOOKUP(A4,Jogos!A:BN,62,0) -> 0.5 | BE4: =VLOOKUP(A4,Jogos!A:BN,63,0) -> 2.07 | BF4: =VLOOKUP(A4,Jogos!A:BN,64,0) -> 24.755 | BG4: =VLOOKUP(A4,Jogos!A:BN,65,0) -> 42.805 | BH4: =VLOOKUP(A4,Jogos!A:BN,66,0) -> 28.715
A5: 1 | B5: Group A | C5: Group | D5: 45822 | E5: 0.83333333 | F5: =VLOOKUP(A5,Jogos!A:N,10,0) -> Evening | G5: Hard Rock Stadium | H5: =VLOOKUP(A5,Jogos!A:L,12,0) -> Open | I5: =VLOOKUP(G5,'Estádios e Cidades'!A:B,2,0) -> Miami Gardens - Flórida | J5: Al Ahly FC | K5: =VLOOKUP(J5,Equipes!A:F,6,0) -> Tropical | L5: =VLOOKUP(J5,Equipes!A:C,3,0) -> 25 | M5: =if(L5<3,"Final",IF(L5<5,"Semi-final",if(L5<9,"Quarter-final",if(L5<17,"Round of 16","Group")))) -> Group | N5: Inter Miami CF | O5: =VLOOKUP(N5,Equipes!A:C,3,0) -> 16 | P5: =if(O5<3,"Final",IF(O5<5,"Semi-final",if(O5<9,"Quarter-final",if(O5<17,"Round of 16","Group")))) -> Round of 16 | Q5: =L5-O5 -> 9 | R5: =VLOOKUP(J5,Equipes!A:B,2,0) -> AlAhly | S5: 8-AlAhly | T5: 8 | U5: HAMDY FATHY | V5: =VLOOKUP(U5,Jogadores!B:C,2,0) -> MF | W5: =VLOOKUP(U5,Jogadores!B:D,3,0) -> 30.849315 | X5: 0 | Y5: =45+AB5 -> 98 | Z5: =VLOOKUP(A5,Jogos!A:L,3,0) -> 48 | AA5: =IF(X5<45,if(Y5>=45,Z5-X5,if(Y5<=Z5,Y5-X5,Z5)),0) -> 48 | AB5: =VLOOKUP(A5,Jogos!A:L,4,0) -> 53 | AC5: =IF(X5<45,if(Y5<=45,0,Y5-45),AB5+45-X5) -> 53 | AF5: =AE5+AC5+AA5 -> 101 | AG5: 10752.5 | AH5: 3938.6 | AI5: 4783.3 | AJ5: 1455.4 | AK5: 470.3 | AL5: 104.8 | AM5: 148 | AN5: 37 | AO5: 37.1 | AP5: =AG5/$AF5 -> 106.4604 | AQ5: =AH5/$AF5 -> 38.99604 | AR5: =AI5/$AF5 -> 47.359406 | AS5: =AQ5+AR5 -> 86.355446 | AT5: =AJ5/$AF5 -> 14.409901 | AU5: =AK5/$AF5 -> 4.6564356 | AV5: =AL5/$AF5 -> 1.0376238 | AW5: =(AK5+AL5)/AF5 -> 5.6940594 | AX5: =AM5/$AF5 -> 1.4653465 | AY5: =AN5/$AF5 -> 0.36633663 | AZ5: =VLOOKUP(A5,Jogos!A:BN,58,0) -> 28.26 | BA5: =VLOOKUP(A5,Jogos!A:BN,59,0) -> 22.895 | BB5: =VLOOKUP(A5,Jogos!A:BN,60,0) -> 72 | BC5: =VLOOKUP(A5,Jogos!A:BN,61,0) -> 27.605 | BD5: =VLOOKUP(A5,Jogos!A:BN,62,0) -> 0.5 | BE5: =VLOOKUP(A5,Jogos!A:BN,63,0) -> 2.07 | BF5: =VLOOKUP(A5,Jogos!A:BN,64,0) -> 24.755 | BG5: =VLOOKUP(A5,Jogos!A:BN,65,0) -> 42.805 | BH5: =VLOOKUP(A5,Jogos!A:BN,66,0) -> 28.715
A6: 1 | B6: Group A | C6: Group | D6: 45822 | E6: 0.83333333 | F6: =VLOOKUP(A6,Jogos!A:N,10,0) -> Evening | G6: Hard Rock Stadium | H6: =VLOOKUP(A6,Jogos!A:L,12,0) -> Open | I6: =VLOOKUP(G6,'Estádios e Cidades'!A:B,2,0) -> Miami Gardens - Flórida | J6: Al Ahly FC | K6: =VLOOKUP(J6,Equipes!A:F,6,0) -> Tropical | L6: =VLOOKUP(J6,Equipes!A:C,3,0) -> 25 | M6: =if(L6<3,"Final",IF(L6<5,"Semi-final",if(L6<9,"Quarter-final",if(L6<17,"Round of 16","Group")))) -> Group | N6: Inter Miami CF | O6: =VLOOKUP(N6,Equipes!A:C,3,0) -> 16 | P6: =if(O6<3,"Final",IF(O6<5,"Semi-final",if(O6<9,"Quarter-final",if(O6<17,"Round of 16","Group")))) -> Round of 16 | Q6: =L6-O6 -> 9 | R6: =VLOOKUP(J6,Equipes!A:B,2,0) -> AlAhly | S6: 9-AlAhly | T6: 9 | U6: WESSAM ABOU ALI | V6: =VLOOKUP(U6,Jogadores!B:C,2,0) -> FW | W6: =VLOOKUP(U6,Jogadores!B:D,3,0) -> 26.580822 | X6: 0 | Y6: 79 | Z6: =VLOOKUP(A6,Jogos!A:L,3,0) -> 48 | AA6: =IF(X6<45,if(Y6>=45,Z6-X6,if(Y6<=Z6,Y6-X6,Z6)),0) -> 48 | AB6: =VLOOKUP(A6,Jogos!A:L,4,0) -> 53 | AC6: =IF(X6<45,if(Y6<=45,0,Y6-45),AB6+45-X6) -> 34 | AF6: =AE6+AC6+AA6 -> 82 | AG6: 8025.4 | AH6: 3449.3 | AI6: 2465.5 | AJ6: 1258.1 | AK6: 600.8 | AL6: 251.6 | AM6: 113 | AN6: 50 | AO6: 34 | AP6: =AG6/$AF6 -> 97.870732 | AQ6: =AH6/$AF6 -> 42.064634 | AR6: =AI6/$AF6 -> 30.067073 | AS6: =AQ6+AR6 -> 72.131707 | AT6: =AJ6/$AF6 -> 15.342683 | AU6: =AK6/$AF6 -> 7.3268293 | AV6: =AL6/$AF6 -> 3.0682927 | AW6: =(AK6+AL6)/AF6 -> 10.395122 | AX6: =AM6/$AF6 -> 1.3780488 | AY6: =AN6/$AF6 -> 0.6097561 | AZ6: =VLOOKUP(A6,Jogos!A:BN,58,0) -> 28.26 | BA6: =VLOOKUP(A6,Jogos!A:BN,59,0) -> 22.895 | BB6: =VLOOKUP(A6,Jogos!A:BN,60,0) -> 72 | BC6: =VLOOKUP(A6,Jogos!A:BN,61,0) -> 27.605 | BD6: =VLOOKUP(A6,Jogos!A:BN,62,0) -> 0.5 | BE6: =VLOOKUP(A6,Jogos!A:BN,63,0) -> 2.07 | BF6: =VLOOKUP(A6,Jogos!A:BN,64,0) -> 24.755 | BG6: =VLOOKUP(A6,Jogos!A:BN,65,0) -> 42.805 | BH6: =VLOOKUP(A6,Jogos!A:BN,66,0) -> 28.715
A7: 1 | B7: Group A | C7: Group | D7: 45822 | E7: 0.83333333 | F7: =VLOOKUP(A7,Jogos!A:N,10,0) -> Evening | G7: Hard Rock Stadium | H7: =VLOOKUP(A7,Jogos!A:L,12,0) -> Open | I7: =VLOOKUP(G7,'Estádios e Cidades'!A:B,2,0) -> Miami Gardens - Flórida | J7: Al Ahly FC | K7: =VLOOKUP(J7,Equipes!A:F,6,0) -> Tropical | L7: =VLOOKUP(J7,Equipes!A:C,3,0) -> 25 | M7: =if(L7<3,"Final",IF(L7<5,"Semi-final",if(L7<9,"Quarter-final",if(L7<17,"Round of 16","Group")))) -> Group | N7: Inter Miami CF | O7: =VLOOKUP(N7,Equipes!A:C,3,0) -> 16 | P7: =if(O7<3,"Final",IF(O7<5,"Semi-final",if(O7<9,"Quarter-final",if(O7<17,"Round of 16","Group")))) -> Round of 16 | Q7: =L7-O7 -> 9 | R7: =VLOOKUP(J7,Equipes!A:B,2,0) -> AlAhly | S7: 13-AlAhly | T7: 13 | U7: MARAWAN ATTIA | V7: =VLOOKUP(U7,Jogadores!B:C,2,0) -> MF | W7: =VLOOKUP(U7,Jogadores!B:D,3,0) -> 26.978082 | X7: 0 | Y7: =45+AB7 -> 98 | Z7: =VLOOKUP(A7,Jogos!A:L,3,0) -> 48 | AA7: =IF(X7<45,if(Y7>=45,Z7-X7,if(Y7<=Z7,Y7-X7,Z7)),0) -> 48 | AB7: =VLOOKUP(A7,Jogos!A:L,4,0) -> 53 | AC7: =IF(X7<45,if(Y7<=45,0,Y7-45),AB7+45-X7) -> 53 | AF7: =AE7+AC7+AA7 -> 101 | AG7: 10304.8 | AH7: 4118.7 | AI7: 4392.1 | AJ7: 1322.2 | AK7: 318.2 | AL7: 153.5 | AM7: 113 | AN7: 31 | AO7: 43.5 | AP7: =AG7/$AF7 -> 102.02772 | AQ7: =AH7/$AF7 -> 40.779208 | AR7: =AI7/$AF7 -> 43.486139 | AS7: =AQ7+AR7 -> 84.265347 | AT7: =AJ7/$AF7 -> 13.091089 | AU7: =AK7/$AF7 -> 3.150495 | AV7: =AL7/$AF7 -> 1.519802 | AW7: =(AK7+AL7)/AF7 -> 4.670297 | AX7: =AM7/$AF7 -> 1.1188119 | AY7: =AN7/$AF7 -> 0.30693069 | AZ7: =VLOOKUP(A7,Jogos!A:BN,58,0) -> 28.26 | BA7: =VLOOKUP(A7,Jogos!A:BN,59,0) -> 22.895 | BB7: =VLOOKUP(A7,Jogos!A:BN,60,0) -> 72 | BC7: =VLOOKUP(A7,Jogos!A:BN,61,0) -> 27.605 | BD7: =VLOOKUP(A7,Jogos!A:BN,62,0) -> 0.5 | BE7: =VLOOKUP(A7,Jogos!A:BN,63,0) -> 2.07 | BF7: =VLOOKUP(A7,Jogos!A:BN,64,0) -> 24.755 | BG7: =VLOOKUP(A7,Jogos!A:BN,65,0) -> 42.805 | BH7: =VLOOKUP(A7,Jogos!A:BN,66,0) -> 28.715
A8: 1 | B8: Group A | C8: Group | D8: 45822 | E8: 0.83333333 | F8: =VLOOKUP(A8,Jogos!A:N,10,0) -> Evening | G8: Hard Rock Stadium | H8: =VLOOKUP(A8,Jogos!A:L,12,0) -> Open | I8: =VLOOKUP(G8,'Estádios e Cidades'!A:B,2,0) -> Miami Gardens - Flórida | J8: Al Ahly FC | K8: =VLOOKUP(J8,Equipes!A:F,6,0) -> Tropical | L8: =VLOOKUP(J8,Equipes!A:C,3,0) -> 25 | M8: =if(L8<3,"Final",IF(L8<5,"Semi-final",if(L8<9,"Quarter-final",if(L8<17,"Round of 16","Group")))) -> Group | N8: Inter Miami CF | O8: =VLOOKUP(N8,Equipes!A:C,3,0) -> 16 | P8: =if(O8<3,"Final",IF(O8<5,"Semi-final",if(O8<9,"Quarter-final",if(O8<17,"Round of 16","Group")))) -> Round of 16 | Q8: =L8-O8 -> 9 | R8: =VLOOKUP(J8,Equipes!A:B,2,0) -> AlAhly | S8: 15-AlAhly | T8: 15 | U8: Achraf DARI | V8: =VLOOKUP(U8,Jogadores!B:C,2,0) -> DF | W8: =VLOOKUP(U8,Jogadores!B:D,3,0) -> 26.246575 | X8: 0 | Y8: =45+AB8 -> 98 | Z8: =VLOOKUP(A8,Jogos!A:L,3,0) -> 48 | AA8: =IF(X8<45,if(Y8>=45,Z8-X8,if(Y8<=Z8,Y8-X8,Z8)),0) -> 48 | AB8: =VLOOKUP(A8,Jogos!A:L,4,0) -> 53 | AC8: =IF(X8<45,if(Y8<=45,0,Y8-45),AB8+45-X8) -> 53 | AF8: =AE8+AC8+AA8 -> 101 | AG8: 9267.2 | AH8: 4048.6 | AI8: 3938.4 | AJ8: 846.4 | AK8: 318.9 | AL8: 114.9 | AM8: 78 | AN8: 29 | AO8: 33 | AP8: =AG8/$AF8 -> 91.754455 | AQ8: =AH8/$AF8 -> 40.085149 | AR8: =AI8/$AF8 -> 38.994059 | AS8: =AQ8+AR8 -> 79.079208 | AT8: =AJ8/$AF8 -> 8.380198 | AU8: =AK8/$AF8 -> 3.1574257 | AV8: =AL8/$AF8 -> 1.1376238 | AW8: =(AK8+AL8)/AF8 -> 4.2950495 | AX8: =AM8/$AF8 -> 0.77227723 | AY8: =AN8/$AF8 -> 0.28712871 | AZ8: =VLOOKUP(A8,Jogos!A:BN,58,0) -> 28.26 | BA8: =VLOOKUP(A8,Jogos!A:BN,59,0) -> 22.895 | BB8: =VLOOKUP(A8,Jogos!A:BN,60,0) -> 72 | BC8: =VLOOKUP(A8,Jogos!A:BN,61,0) -> 27.605 | BD8: =VLOOKUP(A8,Jogos!A:BN,62,0) -> 0.5 | BE8: =VLOOKUP(A8,Jogos!A:BN,63,0) -> 2.07 | BF8: =VLOOKUP(A8,Jogos!A:BN,64,0) -> 24.755 | BG8: =VLOOKUP(A8,Jogos!A:BN,65,0) -> 42.805 | BH8: =VLOOKUP(A8,Jogos!A:BN,66,0) -> 28.715
A9: 1 | B9: Group A | C9: Group | D9: 45822 | E9: 0.83333333 | F9: =VLOOKUP(A9,Jogos!A:N,10,0) -> Evening | G9: Hard Rock Stadium | H9: =VLOOKUP(A9,Jogos!A:L,12,0) -> Open | I9: =VLOOKUP(G9,'Estádios e Cidades'!A:B,2,0) -> Miami Gardens - Flórida | J9: Al Ahly FC | K9: =VLOOKUP(J9,Equipes!A:F,6,0) -> Tropical | L9: =VLOOKUP(J9,Equipes!A:C,3,0) -> 25 | M9: =if(L9<3,"Final",IF(L9<5,"Semi-final",if(L9<9,"Quarter-final",if(L9<17,"Round of 16","Group")))) -> Group | N9: Inter Miami CF | O9: =VLOOKUP(N9,Equipes!A:C,3,0) -> 16 | P9: =if(O9<3,"Final",IF(O9<5,"Semi-final",if(O9<9,"Quarter-final",if(O9<17,"Round of 16","Group")))) -> Round of 16 | Q9: =L9-O9 -> 9 | R9: =VLOOKUP(J9,Equipes!A:B,2,0) -> AlAhly | S9: 22-AlAhly | T9: 22 | U9: EMAM ASHOUR | V9: =VLOOKUP(U9,Jogadores!B:C,2,0) -> MF | W9: =VLOOKUP(U9,Jogadores!B:D,3,0) -> 27.452055 | X9: 0 | Y9: 14 | Z9: =VLOOKUP(A9,Jogos!A:L,3,0) -> 48 | AA9: =IF(X9<45,if(Y9>=45,Z9-X9,if(Y9<=Z9,Y9-X9,Z9)),0) -> 14 | AB9: =VLOOKUP(A9,Jogos!A:L,4,0) -> 53 | AC9: =IF(X9<45,if(Y9<=45,0,Y9-45),AB9+45-X9) -> 0 | AF9: =AE9+AC9+AA9 -> 14 | AG9: 1569.2 | AH9: 463.3 | AI9: 695 | AJ9: 269.9 | AK9: 100.8 | AL9: 40.2 | AM9: 26 | AN9: 9 | AO9: 30 | AP9: =AG9/$AF9 -> 112.08571 | AQ9: =AH9/$AF9 -> 33.092857 | AR9: =AI9/$AF9 -> 49.642857 | AS9: =AQ9+AR9 -> 82.735714 | AT9: =AJ9/$AF9 -> 19.278571 | AU9: =AK9/$AF9 -> 7.2 | AV9: =AL9/$AF9 -> 2.8714286 | AW9: =(AK9+AL9)/AF9 -> 10.071429 | AX9: =AM9/$AF9 -> 1.8571429 | AY9: =AN9/$AF9 -> 0.64285714 | AZ9: =VLOOKUP(A9,Jogos!A:BN,58,0) -> 28.26 | BA9: =VLOOKUP(A9,Jogos!A:BN,59,0) -> 22.895 | BB9: =VLOOKUP(A9,Jogos!A:BN,60,0) -> 72 | BC9: =VLOOKUP(A9,Jogos!A:BN,61,0) -> 27.605 | BD9: =VLOOKUP(A9,Jogos!A:BN,62,0) -> 0.5 | BE9: =VLOOKUP(A9,Jogos!A:BN,63,0) -> 2.07 | BF9: =VLOOKUP(A9,Jogos!A:BN,64,0) -> 24.755 | BG9: =VLOOKUP(A9,Jogos!A:BN,65,0) -> 42.805 | BH9: =VLOOKUP(A9,Jogos!A:BN,66,0) -> 28.715
A10: 1 | B10: Group A | C10: Group | D10: 45822 | E10: 0.83333333 | F10: =VLOOKUP(A10,Jogos!A:N,10,0) -> Evening | G10: Hard Rock Stadium | H10: =VLOOKUP(A10,Jogos!A:L,12,0) -> Open | I10: =VLOOKUP(G10,'Estádios e Cidades'!A:B,2,0) -> Miami Gardens - Flórida | J10: Al Ahly FC | K10: =VLOOKUP(J10,Equipes!A:F,6,0) -> Tropical | L10: =VLOOKUP(J10,Equipes!A:C,3,0) -> 25 | M10: =if(L10<3,"Final",IF(L10<5,"Semi-final",if(L10<9,"Quarter-final",if(L10<17,"Round of 16","Group")))) -> Group | N10: Inter Miami CF | O10: =VLOOKUP(N10,Equipes!A:C,3,0) -> 16 | P10: =if(O10<3,"Final",IF(O10<5,"Semi-final",if(O10<9,"Quarter-final",if(O10<17,"Round of 16","Group")))) -> Round of 16 | Q10: =L10-O10 -> 9 | R10: =VLOOKUP(J10,Equipes!A:B,2,0) -> AlAhly | S10: 30-AlAhly | T10: 30 | U10: MOHAMED HANY | V10: =VLOOKUP(U10,Jogadores!B:C,2,0) -> DF | W10: =VLOOKUP(U10,Jogadores!B:D,3,0) -> 29.526027 | X10: 0 | Y10: =45+AB10 -> 98 | Z10: =VLOOKUP(A10,Jogos!A:L,3,0) -> 48 | AA10: =IF(X10<45,if(Y10>=45,Z10-X10,if(Y10<=Z10,Y10-X10,Z10)),0) -> 48 | AB10: =VLOOKUP(A10,Jogos!A:L,4,0) -> 53 | AC10: =IF(X10<45,if(Y10<=45,0,Y10-45),AB10+45-X10) -> 53 | AF10: =AE10+AC10+AA10 -> 101 | AG10: 9650.4 | AH10: 4190.5 | AI10: 3834.7 | AJ10: 1010.4 | AK10: 430.9 | AL10: 184 | AM10: 80 | AN10: 39 | AO10: 31.4 | AP10: =AG10/$AF10 -> 95.548515 | AQ10: =AH10/$AF10 -> 41.490099 | AR10: =AI10/$AF10 -> 37.967327 | AS10: =AQ10+AR10 -> 79.457426 | AT10: =AJ10/$AF10 -> 10.00396 | AU10: =AK10/$AF10 -> 4.2663366 | AV10: =AL10/$AF10 -> 1.8217822 | AW10: =(AK10+AL10)/AF10 -> 6.0881188 | AX10: =AM10/$AF10 -> 0.79207921 | AY10: =AN10/$AF10 -> 0.38613861 | AZ10: =VLOOKUP(A10,Jogos!A:BN,58,0) -> 28.26 | BA10: =VLOOKUP(A10,Jogos!A:BN,59,0) -> 22.895 | BB10: =VLOOKUP(A10,Jogos!A:BN,60,0) -> 72 | BC10: =VLOOKUP(A10,Jogos!A:BN,61,0) -> 27.605 | BD10: =VLOOKUP(A10,Jogos!A:BN,62,0) -> 0.5 | BE10: =VLOOKUP(A10,Jogos!A:BN,63,0) -> 2.07 | BF10: =VLOOKUP(A10,Jogos!A:BN,64,0) -> 24.755 | BG10: =VLOOKUP(A10,Jogos!A:BN,65,0) -> 42.805 | BH10: =VLOOKUP(A10,Jogos!A:BN,66,0) -> 28.715
A11: 1 | B11: Group A | C11: Group | D11: 45822 | E11: 0.83333333 | F11: =VLOOKUP(A11,Jogos!A:N,10,0) -> Evening | G11: Hard Rock Stadium | H11: =VLOOKUP(A11,Jogos!A:L,12,0) -> Open | I11: =VLOOKUP(G11,'Estádios e Cidades'!A:B,2,0) -> Miami Gardens - Flórida | J11: Al Ahly FC | K11: =VLOOKUP(J11,Equipes!A:F,6,0) -> Tropical | L11: =VLOOKUP(J11,Equipes!A:C,3,0) -> 25 | M11: =if(L11<3,"Final",IF(L11<5,"Semi-final",if(L11<9,"Quarter-final",if(L11<17,"Round of 16","Group")))) -> Group | N11: Inter Miami CF | O11: =VLOOKUP(N11,Equipes!A:C,3,0) -> 16 | P11: =if(O11<3,"Final",IF(O11<5,"Semi-final",if(O11<9,"Quarter-final",if(O11<17,"Round of 16","Group")))) -> Round of 16 | Q11: =L11-O11 -> 9 | R11: =VLOOKUP(J11,Equipes!A:B,2,0) -> AlAhly | S11: 36-AlAhly | T11: 36 | U11: AHMED KOKA | V11: =VLOOKUP(U11,Jogadores!B:C,2,0) -> MF | W11: =VLOOKUP(U11,Jogadores!B:D,3,0) -> 24.082192 | X11: 0 | Y11: =45+AB11 -> 98 | Z11: =VLOOKUP(A11,Jogos!A:L,3,0) -> 48 | AA11: =IF(X11<45,if(Y11>=45,Z11-X11,if(Y11<=Z11,Y11-X11,Z11)),0) -> 48 | AB11: =VLOOKUP(A11,Jogos!A:L,4,0) -> 53 | AC11: =IF(X11<45,if(Y11<=45,0,Y11-45),AB11+45-X11) -> 53 | AF11: =AE11+AC11+AA11 -> 101 | AG11: 9262.7 | AH11: 4260.4 | AI11: 3560.6 | AJ11: 969.3 | AK11: 353 | AL11: 119.4 | AM11: 82 | AN11: 38 | AO11: 31 | AP11: =AG11/$AF11 -> 91.709901 | AQ11: =AH11/$AF11 -> 42.182178 | AR11: =AI11/$AF11 -> 35.253465 | AS11: =AQ11+AR11 -> 77.435644 | AT11: =AJ11/$AF11 -> 9.5970297 | AU11: =AK11/$AF11 -> 3.4950495 | AV11: =AL11/$AF11 -> 1.1821782 | AW11: =(AK11+AL11)/AF11 -> 4.6772277 | AX11: =AM11/$AF11 -> 0.81188119 | AY11: =AN11/$AF11 -> 0.37623762 | AZ11: =VLOOKUP(A11,Jogos!A:BN,58,0) -> 28.26 | BA11: =VLOOKUP(A11,Jogos!A:BN,59,0) -> 22.895 | BB11: =VLOOKUP(A11,Jogos!A:BN,60,0) -> 72 | BC11: =VLOOKUP(A11,Jogos!A:BN,61,0) -> 27.605 | BD11: =VLOOKUP(A11,Jogos!A:BN,62,0) -> 0.5 | BE11: =VLOOKUP(A11,Jogos!A:BN,63,0) -> 2.07 | BF11: =VLOOKUP(A11,Jogos!A:BN,64,0) -> 24.755 | BG11: =VLOOKUP(A11,Jogos!A:BN,65,0) -> 42.805 | BH11: =VLOOKUP(A11,Jogos!A:BN,66,0) -> 28.715
A12: 1 | B12: Group A | C12: Group | D12: 45822 | E12: 0.83333333 | F12: =VLOOKUP(A12,Jogos!A:N,10,0) -> Evening | G12: Hard Rock Stadium | H12: =VLOOKUP(A12,Jogos!A:L,12,0) -> Open | I12: =VLOOKUP(G12,'Estádios e Cidades'!A:B,2,0) -> Miami Gardens - Flórida | J12: Al Ahly FC | K12: =VLOOKUP(J12,Equipes!A:F,6,0) -> Tropical | L12: =VLOOKUP(J12,Equipes!A:C,3,0) -> 25 | M12: =if(L12<3,"Final",IF(L12<5,"Semi-final",if(L12<9,"Quarter-final",if(L12<17,"Round of 16","Group")))) -> Group | N12: Inter Miami CF | O12: =VLOOKUP(N12,Equipes!A:C,3,0) -> 16 | P12: =if(O12<3,"Final",IF(O12<5,"Semi-final",if(O12<9,"Quarter-final",if(O12<17,"Round of 16","Group")))) -> Round of 16 | Q12: =L12-O12 -> 9 | R12: =VLOOKUP(J12,Equipes!A:B,2,0) -> AlAhly | S12: 10-AlAhly | T12: 10 | U12: Nejc GRADISAR | V12: =VLOOKUP(U12,Jogadores!B:C,2,0) -> FW | W12: =VLOOKUP(U12,Jogadores!B:D,3,0) -> 22.991781 | X12: 79 | Y12: =45+AB12 -> 98 | Z12: =VLOOKUP(A12,Jogos!A:L,3,0) -> 48 | AA12: =IF(X12<45,if(Y12>=45,Z12-X12,if(Y12<=Z12,Y12-X12,Z12)),0) -> 0 | AB12: =VLOOKUP(A12,Jogos!A:L,4,0) -> 53 | AC12: =IF(X12<45,if(Y12<=45,0,Y12-45),AB12+45-X12) -> 19 | AF12: =AE12+AC12+AA12 -> 19 | AG12: 2011.5 | AH12: 581.8 | AI12: 874.5 | AJ12: 367 | AK12: 122.4 | AL12: 65.9 | AM12: 28 | AN12: 11 | AO12: 33 | AP12: =AG12/$AF12 -> 105.86842 | AQ12: =AH12/$AF12 -> 30.621053 | AR12: =AI12/$AF12 -> 46.026316 | AS12: =AQ12+AR12 -> 76.647368 | AT12: =AJ12/$AF12 -> 19.315789 | AU12: =AK12/$AF12 -> 6.4421053 | AV12: =AL12/$AF12 -> 3.4684211 | AW12: =(AK12+AL12)/AF12 -> 9.9105263 | AX12: =AM12/$AF12 -> 1.4736842 | AY12: =AN12/$AF12 -> 0.57894737 | AZ12: =VLOOKUP(A12,Jogos!A:BN,58,0) -> 28.26 | BA12: =VLOOKUP(A12,Jogos!A:BN,59,0) -> 22.895 | BB12: =VLOOKUP(A12,Jogos!A:BN,60,0) -> 72 | BC12: =VLOOKUP(A12,Jogos!A:BN,61,0) -> 27.605 | BD12: =VLOOKUP(A12,Jogos!A:BN,62,0) -> 0.5 | BE12: =VLOOKUP(A12,Jogos!A:BN,63,0) -> 2.07 | BF12: =VLOOKUP(A12,Jogos!A:BN,64,0) -> 24.755 | BG12: =VLOOKUP(A12,Jogos!A:BN,65,0) -> 42.805 | BH12: =VLOOKUP(A12,Jogos!A:BN,66,0) -> 28.715
A13: 1 | B13: Group A | C13: Group | D13: 45822 | E13: 0.83333333 | F13: =VLOOKUP(A13,Jogos!A:N,10,0) -> Evening | G13: Hard Rock Stadium | H13: =VLOOKUP(A13,Jogos!A:L,12,0) -> Open | I13: =VLOOKUP(G13,'Estádios e Cidades'!A:B,2,0) -> Miami Gardens - Flórida | J13: Al Ahly FC | K13: =VLOOKUP(J13,Equipes!A:F,6,0) -> Tropical | L13: =VLOOKUP(J13,Equipes!A:C,3,0) -> 25 | M13: =if(L13<3,"Final",IF(L13<5,"Semi-final",if(L13<9,"Quarter-final",if(L13<17,"Round of 16","Group")))) -> Group | N13: Inter Miami CF | O13: =VLOOKUP(N13,Equipes!A:C,3,0) -> 16 | P13: =if(O13<3,"Final",IF(O13<5,"Semi-final",if(O13<9,"Quarter-final",if(O13<17,"Round of 16","Group")))) -> Round of 16 | Q13: =L13-O13 -> 9 | R13: =VLOOKUP(J13,Equipes!A:B,2,0) -> AlAhly | S13: 14-AlAhly | T13: 14 | U13: HUSSEIN ELSHAHAT | V13: =VLOOKUP(U13,Jogadores!B:C,2,0) -> MF | W13: =VLOOKUP(U13,Jogadores!B:D,3,0) -> 33.123288 | X13: 65 | Y13: =45+AB13 -> 98 | Z13: =VLOOKUP(A13,Jogos!A:L,3,0) -> 48 | AA13: =IF(X13<45,if(Y13>=45,Z13-X13,if(Y13<=Z13,Y13-X13,Z13)),0) -> 0 | AB13: =VLOOKUP(A13,Jogos!A:L,4,0) -> 53 | AC13: =IF(X13<45,if(Y13<=45,0,Y13-45),AB13+45-X13) -> 33 | AF13: =AE13+AC13+AA13 -> 33 | AG13: 3166.6 | AH13: 1508.1 | AI13: 1054.1 | AJ13: 411 | AK13: 142.9 | AL13: 50.6 | AM13: 41 | AN13: 15 | AO13: 31.5 | AP13: =AG13/$AF13 -> 95.957576 | AQ13: =AH13/$AF13 -> 45.7 | AR13: =AI13/$AF13 -> 31.942424 | AS13: =AQ13+AR13 -> 77.642424 | AT13: =AJ13/$AF13 -> 12.454545 | AU13: =AK13/$AF13 -> 4.330303 | AV13: =AL13/$AF13 -> 1.5333333 | AW13: =(AK13+AL13)/AF13 -> 5.8636364 | AX13: =AM13/$AF13 -> 1.2424242 | AY13: =AN13/$AF13 -> 0.45454545 | AZ13: =VLOOKUP(A13,Jogos!A:BN,58,0) -> 28.26 | BA13: =VLOOKUP(A13,Jogos!A:BN,59,0) -> 22.895 | BB13: =VLOOKUP(A13,Jogos!A:BN,60,0) -> 72 | BC13: =VLOOKUP(A13,Jogos!A:BN,61,0) -> 27.605 | BD13: =VLOOKUP(A13,Jogos!A:BN,62,0) -> 0.5 | BE13: =VLOOKUP(A13,Jogos!A:BN,63,0) -> 2.07 | BF13: =VLOOKUP(A13,Jogos!A:BN,64,0) -> 24.755 | BG13: =VLOOKUP(A13,Jogos!A:BN,65,0) -> 42.805 | BH13: =VLOOKUP(A13,Jogos!A:BN,66,0) -> 28.715
A14: 1 | B14: Group A | C14: Group | D14: 45822 | E14: 0.83333333 | F14: =VLOOKUP(A14,Jogos!A:N,10,0) -> Evening | G14: Hard Rock Stadium | H14: =VLOOKUP(A14,Jogos!A:L,12,0) -> Open | I14: =VLOOKUP(G14,'Estádios e Cidades'!A:B,2,0) -> Miami Gardens - Flórida | J14: Al Ahly FC | K14: =VLOOKUP(J14,Equipes!A:F,6,0) -> Tropical | L14: =VLOOKUP(J14,Equipes!A:C,3,0) -> 25 | M14: =if(L14<3,"Final",IF(L14<5,"Semi-final",if(L14<9,"Quarter-final",if(L14<17,"Round of 16","Group")))) -> Group | N14: Inter Miami CF | O14: =VLOOKUP(N14,Equipes!A:C,3,0) -> 16 | P14: =if(O14<3,"Final",IF(O14<5,"Semi-final",if(O14<9,"Quarter-final",if(O14<17,"Round of 16","Group")))) -> Round of 16 | Q14: =L14-O14 -> 9 | R14: =VLOOKUP(J14,Equipes!A:B,2,0) -> AlAhly | S14: 19-AlAhly | T14: 19 | U14: MOHAMED AFSHA | V14: =VLOOKUP(U14,Jogadores!B:C,2,0) -> MF | W14: =VLOOKUP(U14,Jogadores!B:D,3,0) -> 29.169863 | X14: 79 | Y14: =45+AB14 -> 98 | Z14: =VLOOKUP(A14,Jogos!A:L,3,0) -> 48 | AA14: =IF(X14<45,if(Y14>=45,Z14-X14,if(Y14<=Z14,Y14-X14,Z14)),0) -> 0 | AB14: =VLOOKUP(A14,Jogos!A:L,4,0) -> 53 | AC14: =IF(X14<45,if(Y14<=45,0,Y14-45),AB14+45-X14) -> 19 | AF14: =AE14+AC14+AA14 -> 19 | AG14: 1947.2 | AH14: 680.6 | AI14: 819.5 | AJ14: 276.4 | AK14: 117.5 | AL14: 53.2 | AM14: 26 | AN14: 9 | AO14: 34.7 | AP14: =AG14/$AF14 -> 102.48421 | AQ14: =AH14/$AF14 -> 35.821053 | AR14: =AI14/$AF14 -> 43.131579 | AS14: =AQ14+AR14 -> 78.952632 | AT14: =AJ14/$AF14 -> 14.547368 | AU14: =AK14/$AF14 -> 6.1842105 | AV14: =AL14/$AF14 -> 2.8 | AW14: =(AK14+AL14)/AF14 -> 8.9842105 | AX14: =AM14/$AF14 -> 1.3684211 | AY14: =AN14/$AF14 -> 0.47368421 | AZ14: =VLOOKUP(A14,Jogos!A:BN,58,0) -> 28.26 | BA14: =VLOOKUP(A14,Jogos!A:BN,59,0) -> 22.895 | BB14: =VLOOKUP(A14,Jogos!A:BN,60,0) -> 72 | BC14: =VLOOKUP(A14,Jogos!A:BN,61,0) -> 27.605 | BD14: =VLOOKUP(A14,Jogos!A:BN,62,0) -> 0.5 | BE14: =VLOOKUP(A14,Jogos!A:BN,63,0) -> 2.07 | BF14: =VLOOKUP(A14,Jogos!A:BN,64,0) -> 24.755 | BG14: =VLOOKUP(A14,Jogos!A:BN,65,0) -> 42.805 | BH14: =VLOOKUP(A14,Jogos!A:BN,66,0) -> 28.715
A15: 1 | B15: Group A | C15: Group | D15: 45822 | E15: 0.83333333 | F15: =VLOOKUP(A15,Jogos!A:N,10,0) -> Evening | G15: Hard Rock Stadium | H15: =VLOOKUP(A15,Jogos!A:L,12,0) -> Open | I15: =VLOOKUP(G15,'Estádios e Cidades'!A:B,2,0) -> Miami Gardens - Flórida | J15: Al Ahly FC | K15: =VLOOKUP(J15,Equipes!A:F,6,0) -> Tropical | L15: =VLOOKUP(J15,Equipes!A:C,3,0) -> 25 | M15: =if(L15<3,"Final",IF(L15<5,"Semi-final",if(L15<9,"Quarter-final",if(L15<17,"Round of 16","Group")))) -> Group | N15: Inter Miami CF | O15: =VLOOKUP(N15,Equipes!A:C,3,0) -> 16 | P15: =if(O15<3,"Final",IF(O15<5,"Semi-final",if(O15<9,"Quarter-final",if(O15<17,"Round of 16","Group")))) -> Round of 16 | Q15: =L15-O15 -> 9 | R15: =VLOOKUP(J15,Equipes!A:B,2,0) -> AlAhly | S15: 25-AlAhly | T15: 25 | U15: ZIZO | V15: =VLOOKUP(U15,Jogadores!B:C,2,0) -> MF | W15: =VLOOKUP(U15,Jogadores!B:D,3,0) -> 29.567123 | X15: 14 | Y15: 79 | Z15: =VLOOKUP(A15,Jogos!A:L,3,0) -> 48 | AA15: =IF(X15<45,if(Y15>=45,Z15-X15,if(Y15<=Z15,Y15-X15,Z15)),0) -> 34 | AB15: =VLOOKUP(A15,Jogos!A:L,4,0) -> 53 | AC15: =IF(X15<45,if(Y15<=45,0,Y15-45),AB15+45-X15) -> 34 | AF15: =AE15+AC15+AA15 -> 68 | AG15: 6962.4 | AH15: 2600.4 | AI15: 2987.4 | AJ15: 823.1 | AK15: 341.6 | AL15: 209.9 | AM15: 73 | AN15: 32 | AO15: 44.3 | AP15: =AG15/$AF15 -> 102.38824 | AQ15: =AH15/$AF15 -> 38.241176 | AR15: =AI15/$AF15 -> 43.932353 | AS15: =AQ15+AR15 -> 82.173529 | AT15: =AJ15/$AF15 -> 12.104412 | AU15: =AK15/$AF15 -> 5.0235294 | AV15: =AL15/$AF15 -> 3.0867647 | AW15: =(AK15+AL15)/AF15 -> 8.1102941 | AX15: =AM15/$AF15 -> 1.0735294 | AY15: =AN15/$AF15 -> 0.47058824 | AZ15: =VLOOKUP(A15,Jogos!A:BN,58,0) -> 28.26 | BA15: =VLOOKUP(A15,Jogos!A:BN,59,0) -> 22.895 | BB15: =VLOOKUP(A15,Jogos!A:BN,60,0) -> 72 | BC15: =VLOOKUP(A15,Jogos!A:BN,61,0) -> 27.605 | BD15: =VLOOKUP(A15,Jogos!A:BN,62,0) -> 0.5 | BE15: =VLOOKUP(A15,Jogos!A:BN,63,0) -> 2.07 | BF15: =VLOOKUP(A15,Jogos!A:BN,64,0) -> 24.755 | BG15: =VLOOKUP(A15,Jogos!A:BN,65,0) -> 42.805 | BH15: =VLOOKUP(A15,Jogos!A:BN,66,0) -> 28.715
A16: 1 | B16: Group A | C16: Group | D16: 45822 | E16: 0.83333333 | F16: =VLOOKUP(A16,Jogos!A:N,10,0) -> Evening | G16: Hard Rock Stadium | H16: =VLOOKUP(A16,Jogos!A:L,12,0) -> Open | I16: =VLOOKUP(G16,'Estádios e Cidades'!A:B,2,0) -> Miami Gardens - Flórida | J16: Al Ahly FC | K16: =VLOOKUP(J16,Equipes!A:F,6,0) -> Tropical | L16: =VLOOKUP(J16,Equipes!A:C,3,0) -> 25 | M16: =if(L16<3,"Final",IF(L16<5,"Semi-final",if(L16<9,"Quarter-final",if(L16<17,"Round of 16","Group")))) -> Group | N16: Inter Miami CF | O16: =VLOOKUP(N16,Equipes!A:C,3,0) -> 16 | P16: =if(O16<3,"Final",IF(O16<5,"Semi-final",if(O16<9,"Quarter-final",if(O16<17,"Round of 16","Group")))) -> Round of 16 | Q16: =L16-O16 -> 9 | R16: =VLOOKUP(J16,Equipes!A:B,2,0) -> AlAhly | S16: 29-AlAhly | T16: 29 | U16: TAHER MOHAMED | V16: =VLOOKUP(U16,Jogadores!B:C,2,0) -> MF | W16: =VLOOKUP(U16,Jogadores!B:D,3,0) -> 28.087671 | X16: 65 | Y16: =45+AB16 -> 98 | Z16: =VLOOKUP(A16,Jogos!A:L,3,0) -> 48 | AA16: =IF(X16<45,if(Y16>=45,Z16-X16,if(Y16<=Z16,Y16-X16,Z16)),0) -> 0 | AB16: =VLOOKUP(A16,Jogos!A:L,4,0) -> 53 | AC16: =IF(X16<45,if(Y16<=45,0,Y16-45),AB16+45-X16) -> 33 | AF16: =AE16+AC16+AA16 -> 33 | AG16: 3344 | AH16: 1389.6 | AI16: 1019.8 | AJ16: 426.6 | AK16: 318 | AL16: 190 | AM16: 40 | AN16: 28 | AO16: 35 | AP16: =AG16/$AF16 -> 101.33333 | AQ16: =AH16/$AF16 -> 42.109091 | AR16: =AI16/$AF16 -> 30.90303 | AS16: =AQ16+AR16 -> 73.012121 | AT16: =AJ16/$AF16 -> 12.927273 | AU16: =AK16/$AF16 -> 9.6363636 | AV16: =AL16/$AF16 -> 5.7575758 | AW16: =(AK16+AL16)/AF16 -> 15.393939 | AX16: =AM16/$AF16 -> 1.2121212 | AY16: =AN16/$AF16 -> 0.84848485 | AZ16: =VLOOKUP(A16,Jogos!A:BN,58,0) -> 28.26 | BA16: =VLOOKUP(A16,Jogos!A:BN,59,0) -> 22.895 | BB16: =VLOOKUP(A16,Jogos!A:BN,60,0) -> 72 | BC16: =VLOOKUP(A16,Jogos!A:BN,61,0) -> 27.605 | BD16: =VLOOKUP(A16,Jogos!A:BN,62,0) -> 0.5 | BE16: =VLOOKUP(A16,Jogos!A:BN,63,0) -> 2.07 | BF16: =VLOOKUP(A16,Jogos!A:BN,64,0) -> 24.755 | BG16: =VLOOKUP(A16,Jogos!A:BN,65,0) -> 42.805 | BH16: =VLOOKUP(A16,Jogos!A:BN,66,0) -> 28.715
A17: 1 | B17: Group A | C17: Group | D17: 45822 | E17: 0.83333333 | F17: =VLOOKUP(A17,Jogos!A:N,10,0) -> Evening | G17: Hard Rock Stadium | H17: =VLOOKUP(A17,Jogos!A:L,12,0) -> Open | I17: =VLOOKUP(G17,'Estádios e Cidades'!A:B,2,0) -> Miami Gardens - Flórida | J17: Inter Miami CF | K17: =VLOOKUP(J17,Equipes!A:F,6,0) -> Tropical | L17: =VLOOKUP(J17,Equipes!A:C,3,0) -> 16 | M17: =if(L17<3,"Final",IF(L17<5,"Semi-final",if(L17<9,"Quarter-final",if(L17<17,"Round of 16","Group")))) -> Round of 16 | N17: Al Ahly FC | O17: =VLOOKUP(N17,Equipes!A:C,3,0) -> 25 | P17: =if(O17<3,"Final",IF(O17<5,"Semi-final",if(O17<9,"Quarter-final",if(O17<17,"Round of 16","Group")))) -> Group | Q17: =L17-O17 -> -9 | R17: =VLOOKUP(J17,Equipes!A:B,2,0) -> InterMiami | S17: 5-InterMiami | T17: 5 | U17: Sergio BUSQUETS | V17: =VLOOKUP(U17,Jogadores!B:C,2,0) -> MF | W17: =VLOOKUP(U17,Jogadores!B:D,3,0) -> 37.057534 | X17: 0 | Y17: =45+AB17 -> 98 | Z17: =VLOOKUP(A17,Jogos!A:L,3,0) -> 48 | AA17: =IF(X17<45,if(Y17>=45,Z17-X17,if(Y17<=Z17,Y17-X17,Z17)),0) -> 48 | AB17: =VLOOKUP(A17,Jogos!A:L,4,0) -> 53 | AC17: =IF(X17<45,if(Y17<=45,0,Y17-45),AB17+45-X17) -> 53 | AF17: =AE17+AC17+AA17 -> 101 | AG17: 10337.7 | AH17: 4136.7 | AI17: 4584.2 | AJ17: 1180.1 | AK17: 323 | AL17: 113.8 | AM17: 118 | AN17: 26 | AO17: 35.5 | AP17: =AG17/$AF17 -> 102.35347 | AQ17: =AH17/$AF17 -> 40.957426 | AR17: =AI17/$AF17 -> 45.388119 | AS17: =AQ17+AR17 -> 86.345545 | AT17: =AJ17/$AF17 -> 11.684158 | AU17: =AK17/$AF17 -> 3.1980198 | AV17: =AL17/$AF17 -> 1.1267327 | AW17: =(AK17+AL17)/AF17 -> 4.3247525 | AX17: =AM17/$AF17 -> 1.1683168 | AY17: =AN17/$AF17 -> 0.25742574 | AZ17: =VLOOKUP(A17,Jogos!A:BN,58,0) -> 28.26 | BA17: =VLOOKUP(A17,Jogos!A:BN,59,0) -> 22.895 | BB17: =VLOOKUP(A17,Jogos!A:BN,60,0) -> 72 | BC17: =VLOOKUP(A17,Jogos!A:BN,61,0) -> 27.605 | BD17: =VLOOKUP(A17,Jogos!A:BN,62,0) -> 0.5 | BE17: =VLOOKUP(A17,Jogos!A:BN,63,0) -> 2.07 | BF17: =VLOOKUP(A17,Jogos!A:BN,64,0) -> 24.755 | BG17: =VLOOKUP(A17,Jogos!A:BN,65,0) -> 42.805 | BH17: =VLOOKUP(A17,Jogos!A:BN,66,0) -> 28.715
A18: 1 | B18: Group A | C18: Group | D18: 45822 | E18: 0.83333333 | F18: =VLOOKUP(A18,Jogos!A:N,10,0) -> Evening | G18: Hard Rock Stadium | H18: =VLOOKUP(A18,Jogos!A:L,12,0) -> Open | I18: =VLOOKUP(G18,'Estádios e Cidades'!A:B,2,0) -> Miami Gardens - Flórida | J18: Inter Miami CF | K18: =VLOOKUP(J18,Equipes!A:F,6,0) -> Tropical | L18: =VLOOKUP(J18,Equipes!A:C,3,0) -> 16 | M18: =if(L18<3,"Final",IF(L18<5,"Semi-final",if(L18<9,"Quarter-final",if(L18<17,"Round of 16","Group")))) -> Round of 16 | N18: Al Ahly FC | O18: =VLOOKUP(N18,Equipes!A:C,3,0) -> 25 | P18: =if(O18<3,"Final",IF(O18<5,"Semi-final",if(O18<9,"Quarter-final",if(O18<17,"Round of 16","Group")))) -> Group | Q18: =L18-O18 -> -9 | R18: =VLOOKUP(J18,Equipes!A:B,2,0) -> InterMiami | S18: 6-InterMiami | T18: 6 | U18: Tomas AVILES | V18: =VLOOKUP(U18,Jogadores!B:C,2,0) -> DF | W18: =VLOOKUP(U18,Jogadores!B:D,3,0) -> 21.49589 | X18: 0 | Y18: 45 | Z18: =VLOOKUP(A18,Jogos!A:L,3,0) -> 48 | AA18: =IF(X18<45,if(Y18>=45,Z18-X18,if(Y18<=Z18,Y18-X18,Z18)),0) -> 48 | AB18: =VLOOKUP(A18,Jogos!A:L,4,0) -> 53 | AC18: =IF(X18<45,if(Y18<=45,0,Y18-45),AB18+45-X18) -> 0 | AF18: =AE18+AC18+AA18 -> 48 | AG18: 4755.7 | AH18: 2093.4 | AI18: 1818.4 | AJ18: 443.1 | AK18: 210.6 | AL18: 190.2 | AM18: 38 | AN18: 20 | AO18: 35.3 | AP18: =AG18/$AF18 -> 99.077083 | AQ18: =AH18/$AF18 -> 43.6125 | AR18: =AI18/$AF18 -> 37.883333 | AS18: =AQ18+AR18 -> 81.495833 | AT18: =AJ18/$AF18 -> 9.23125 | AU18: =AK18/$AF18 -> 4.3875 | AV18: =AL18/$AF18 -> 3.9625 | AW18: =(AK18+AL18)/AF18 -> 8.35 | AX18: =AM18/$AF18 -> 0.79166667 | AY18: =AN18/$AF18 -> 0.41666667 | AZ18: =VLOOKUP(A18,Jogos!A:BN,58,0) -> 28.26 | BA18: =VLOOKUP(A18,Jogos!A:BN,59,0) -> 22.895 | BB18: =VLOOKUP(A18,Jogos!A:BN,60,0) -> 72 | BC18: =VLOOKUP(A18,Jogos!A:BN,61,0) -> 27.605 | BD18: =VLOOKUP(A18,Jogos!A:BN,62,0) -> 0.5 | BE18: =VLOOKUP(A18,Jogos!A:BN,63,0) -> 2.07 | BF18: =VLOOKUP(A18,Jogos!A:BN,64,0) -> 24.755 | BG18: =VLOOKUP(A18,Jogos!A:BN,65,0) -> 42.805 | BH18: =VLOOKUP(A18,Jogos!A:BN,66,0) -> 28.715
A19: 1 | B19: Group A | C19: Group | D19: 45822 | E19: 0.83333333 | F19: =VLOOKUP(A19,Jogos!A:N,10,0) -> Evening | G19: Hard Rock Stadium | H19: =VLOOKUP(A19,Jogos!A:L,12,0) -> Open | I19: =VLOOKUP(G19,'Estádios e Cidades'!A:B,2,0) -> Miami Gardens - Flórida | J19: Inter Miami CF | K19: =VLOOKUP(J19,Equipes!A:F,6,0) -> Tropical | L19: =VLOOKUP(J19,Equipes!A:C,3,0) -> 16 | M19: =if(L19<3,"Final",IF(L19<5,"Semi-final",if(L19<9,"Quarter-final",if(L19<17,"Round of 16","Group")))) -> Round of 16 | N19: Al Ahly FC | O19: =VLOOKUP(N19,Equipes!A:C,3,0) -> 25 | P19: =if(O19<3,"Final",IF(O19<5,"Semi-final",if(O19<9,"Quarter-final",if(O19<17,"Round of 16","Group")))) -> Group | Q19: =L19-O19 -> -9 | R19: =VLOOKUP(J19,Equipes!A:B,2,0) -> InterMiami | S19: 8-InterMiami | T19: 8 | U19: Telasco SEGOVIA | V19: =VLOOKUP(U19,Jogadores!B:C,2,0) -> MF | W19: =VLOOKUP(U19,Jogadores!B:D,3,0) -> 22.336986 | X19: 0 | Y19: 73 | Z19: =VLOOKUP(A19,Jogos!A:L,3,0) -> 48 | AA19: =IF(X19<45,if(Y19>=45,Z19-X19,if(Y19<=Z19,Y19-X19,Z19)),0) -> 48 | AB19: =VLOOKUP(A19,Jogos!A:L,4,0) -> 53 | AC19: =IF(X19<45,if(Y19<=45,0,Y19-45),AB19+45-X19) -> 28 | AF19: =AE19+AC19+AA19 -> 76 | AG19: 8479.5 | AH19: 3200.6 | AI19: 3218.6 | AJ19: 1352.1 | AK19: 559 | AL19: 149.2 | AM19: 120 | AN19: 45 | AO19: 38.9 | AP19: =AG19/$AF19 -> 111.57237 | AQ19: =AH19/$AF19 -> 42.113158 | AR19: =AI19/$AF19 -> 42.35 | AS19: =AQ19+AR19 -> 84.463158 | AT19: =AJ19/$AF19 -> 17.790789 | AU19: =AK19/$AF19 -> 7.3552632 | AV19: =AL19/$AF19 -> 1.9631579 | AW19: =(AK19+AL19)/AF19 -> 9.3184211 | AX19: =AM19/$AF19 -> 1.5789474 | AY19: =AN19/$AF19 -> 0.59210526 | AZ19: =VLOOKUP(A19,Jogos!A:BN,58,0) -> 28.26 | BA19: =VLOOKUP(A19,Jogos!A:BN,59,0) -> 22.895 | BB19: =VLOOKUP(A19,Jogos!A:BN,60,0) -> 72 | BC19: =VLOOKUP(A19,Jogos!A:BN,61,0) -> 27.605 | BD19: =VLOOKUP(A19,Jogos!A:BN,62,0) -> 0.5 | BE19: =VLOOKUP(A19,Jogos!A:BN,63,0) -> 2.07 | BF19: =VLOOKUP(A19,Jogos!A:BN,64,0) -> 24.755 | BG19: =VLOOKUP(A19,Jogos!A:BN,65,0) -> 42.805 | BH19: =VLOOKUP(A19,Jogos!A:BN,66,0) -> 28.715
A20: 1 | B20: Group A | C20: Group | D20: 45822 | E20: 0.83333333 | F20: =VLOOKUP(A20,Jogos!A:N,10,0) -> Evening | G20: Hard Rock Stadium | H20: =VLOOKUP(A20,Jogos!A:L,12,0) -> Open | I20: =VLOOKUP(G20,'Estádios e Cidades'!A:B,2,0) -> Miami Gardens - Flórida | J20: Inter Miami CF | K20: =VLOOKUP(J20,Equipes!A:F,6,0) -> Tropical | L20: =VLOOKUP(J20,Equipes!A:C,3,0) -> 16 | M20: =if(L20<3,"Final",IF(L20<5,"Semi-final",if(L20<9,"Quarter-final",if(L20<17,"Round of 16","Group")))) -> Round of 16 | N20: Al Ahly FC | O20: =VLOOKUP(N20,Equipes!A:C,3,0) -> 25 | P20: =if(O20<3,"Final",IF(O20<5,"Semi-final",if(O20<9,"Quarter-final",if(O20<17,"Round of 16","Group")))) -> Group | Q20: =L20-O20 -> -9 | R20: =VLOOKUP(J20,Equipes!A:B,2,0) -> InterMiami | S20: 9-InterMiami | T20: 9 | U20: Luis SUAREZ | V20: =VLOOKUP(U20,Jogadores!B:C,2,0) -> FW | W20: =VLOOKUP(U20,Jogadores!B:D,3,0) -> 38.534247 | X20: 0 | Y20: =45+AB20 -> 98 | Z20: =VLOOKUP(A20,Jogos!A:L,3,0) -> 48 | AA20: =IF(X20<45,if(Y20>=45,Z20-X20,if(Y20<=Z20,Y20-X20,Z20)),0) -> 48 | AB20: =VLOOKUP(A20,Jogos!A:L,4,0) -> 53 | AC20: =IF(X20<45,if(Y20<=45,0,Y20-45),AB20+45-X20) -> 53 | AF20: =AE20+AC20+AA20 -> 101 | AG20: 9859.9 | AH20: 3876.1 | AI20: 4058.4 | AJ20: 1326 | AK20: 470 | AL20: 129.5 | AM20: 113 | AN20: 40 | AO20: 30.4 | AP20: =AG20/$AF20 -> 97.622772 | AQ20: =AH20/$AF20 -> 38.377228 | AR20: =AI20/$AF20 -> 40.182178 | AS20: =AQ20+AR20 -> 78.559406 | AT20: =AJ20/$AF20 -> 13.128713 | AU20: =AK20/$AF20 -> 4.6534653 | AV20: =AL20/$AF20 -> 1.2821782 | AW20: =(AK20+AL20)/AF20 -> 5.9356436 | AX20: =AM20/$AF20 -> 1.1188119 | AY20: =AN20/$AF20 -> 0.3960396 | AZ20: =VLOOKUP(A20,Jogos!A:BN,58,0) -> 28.26 | BA20: =VLOOKUP(A20,Jogos!A:BN,59,0) -> 22.895 | BB20: =VLOOKUP(A20,Jogos!A:BN,60,0) -> 72 | BC20: =VLOOKUP(A20,Jogos!A:BN,61,0) -> 27.605 | BD20: =VLOOKUP(A20,Jogos!A:BN,62,0) -> 0.5 | BE20: =VLOOKUP(A20,Jogos!A:BN,63,0) -> 2.07 | BF20: =VLOOKUP(A20,Jogos!A:BN,64,0) -> 24.755 | BG20: =VLOOKUP(A20,Jogos!A:BN,65,0) -> 42.805 | BH20: =VLOOKUP(A20,Jogos!A:BN,66,0) -> 28.715
A21: 1 | B21: Group A | C21: Group | D21: 45822 | E21: 0.83333333 | F21: =VLOOKUP(A21,Jogos!A:N,10,0) -> Evening | G21: Hard Rock Stadium | H21: =VLOOKUP(A21,Jogos!A:L,12,0) -> Open | I21: =VLOOKUP(G21,'Estádios e Cidades'!A:B,2,0) -> Miami Gardens - Flórida | J21: Inter Miami CF | K21: =VLOOKUP(J21,Equipes!A:F,6,0) -> Tropical | L21: =VLOOKUP(J21,Equipes!A:C,3,0) -> 16 | M21: =if(L21<3,"Final",IF(L21<5,"Semi-final",if(L21<9,"Quarter-final",if(L21<17,"Round of 16","Group")))) -> Round of 16 | N21: Al Ahly FC | O21: =VLOOKUP(N21,Equipes!A:C,3,0) -> 25 | P21: =if(O21<3,"Final",IF(O21<5,"Semi-final",if(O21<9,"Quarter-final",if(O21<17,"Round of 16","Group")))) -> Group | Q21: =L21-O21 -> -9 | R21: =VLOOKUP(J21,Equipes!A:B,2,0) -> InterMiami | S21: 10-InterMiami | T21: 10 | U21: Lionel MESSI | V21: =VLOOKUP(U21,Jogadores!B:C,2,0) -> FW | W21: =VLOOKUP(U21,Jogadores!B:D,3,0) -> 38.120548 | X21: 0 | Y21: =45+AB21 -> 98 | Z21: =VLOOKUP(A21,Jogos!A:L,3,0) -> 48 | AA21: =IF(X21<45,if(Y21>=45,Z21-X21,if(Y21<=Z21,Y21-X21,Z21)),0) -> 48 | AB21: =VLOOKUP(A21,Jogos!A:L,4,0) -> 53 | AC21: =IF(X21<45,if(Y21<=45,0,Y21-45),AB21+45-X21) -> 53 | AF21: =AE21+AC21+AA21 -> 101 | AG21: 7429.2 | AH21: 4891.8 | AI21: 1430.8 | AJ21: 727.4 | AK21: 280.5 | AL21: 98.7 | AM21: 66 | AN21: 27 | AO21: 35.4 | AP21: =AG21/$AF21 -> 73.556436 | AQ21: =AH21/$AF21 -> 48.433663 | AR21: =AI21/$AF21 -> 14.166337 | AS21: =AQ21+AR21 -> 62.6 | AT21: =AJ21/$AF21 -> 7.2019802 | AU21: =AK21/$AF21 -> 2.7772277 | AV21: =AL21/$AF21 -> 0.97722772 | AW21: =(AK21+AL21)/AF21 -> 3.7544554 | AX21: =AM21/$AF21 -> 0.65346535 | AY21: =AN21/$AF21 -> 0.26732673 | AZ21: =VLOOKUP(A21,Jogos!A:BN,58,0) -> 28.26 | BA21: =VLOOKUP(A21,Jogos!A:BN,59,0) -> 22.895 | BB21: =VLOOKUP(A21,Jogos!A:BN,60,0) -> 72 | BC21: =VLOOKUP(A21,Jogos!A:BN,61,0) -> 27.605 | BD21: =VLOOKUP(A21,Jogos!A:BN,62,0) -> 0.5 | BE21: =VLOOKUP(A21,Jogos!A:BN,63,0) -> 2.07 | BF21: =VLOOKUP(A21,Jogos!A:BN,64,0) -> 24.755 | BG21: =VLOOKUP(A21,Jogos!A:BN,65,0) -> 42.805 | BH21: =VLOOKUP(A21,Jogos!A:BN,66,0) -> 28.715
A22: 1 | B22: Group A | C22: Group | D22: 45822 | E22: 0.83333333 | F22: =VLOOKUP(A22,Jogos!A:N,10,0) -> Evening | G22: Hard Rock Stadium | H22: =VLOOKUP(A22,Jogos!A:L,12,0) -> Open | I22: =VLOOKUP(G22,'Estádios e Cidades'!A:B,2,0) -> Miami Gardens - Flórida | J22: Inter Miami CF | K22: =VLOOKUP(J22,Equipes!A:F,6,0) -> Tropical | L22: =VLOOKUP(J22,Equipes!A:C,3,0) -> 16 | M22: =if(L22<3,"Final",IF(L22<5,"Semi-final",if(L22<9,"Quarter-final",if(L22<17,"Round of 16","Group")))) -> Round of 16 | N22: Al Ahly FC | O22: =VLOOKUP(N22,Equipes!A:C,3,0) -> 25 | P22: =if(O22<3,"Final",IF(O22<5,"Semi-final",if(O22<9,"Quarter-final",if(O22<17,"Round of 16","Group")))) -> Group | Q22: =L22-O22 -> -9 | R22: =VLOOKUP(J22,Equipes!A:B,2,0) -> InterMiami | S22: 17-InterMiami | T22: 17 | U22: Ian FRAY | V22: =VLOOKUP(U22,Jogadores!B:C,2,0) -> DF | W22: =VLOOKUP(U22,Jogadores!B:D,3,0) -> 22.923288 | X22: 0 | Y22: =45+AB22 -> 98 | Z22: =VLOOKUP(A22,Jogos!A:L,3,0) -> 48 | AA22: =IF(X22<45,if(Y22>=45,Z22-X22,if(Y22<=Z22,Y22-X22,Z22)),0) -> 48 | AB22: =VLOOKUP(A22,Jogos!A:L,4,0) -> 53 | AC22: =IF(X22<45,if(Y22<=45,0,Y22-45),AB22+45-X22) -> 53 | AF22: =AE22+AC22+AA22 -> 101 | AG22: 10352 | AH22: 4083.5 | AI22: 4359.6 | AJ22: 1123.4 | AK22: 439.5 | AL22: 346 | AM22: 86 | AN22: 44 | AO22: 35.5 | AP22: =AG22/$AF22 -> 102.49505 | AQ22: =AH22/$AF22 -> 40.430693 | AR22: =AI22/$AF22 -> 43.164356 | AS22: =AQ22+AR22 -> 83.59505 | AT22: =AJ22/$AF22 -> 11.122772 | AU22: =AK22/$AF22 -> 4.3514851 | AV22: =AL22/$AF22 -> 3.4257426 | AW22: =(AK22+AL22)/AF22 -> 7.7772277 | AX22: =AM22/$AF22 -> 0.85148515 | AY22: =AN22/$AF22 -> 0.43564356 | AZ22: =VLOOKUP(A22,Jogos!A:BN,58,0) -> 28.26 | BA22: =VLOOKUP(A22,Jogos!A:BN,59,0) -> 22.895 | BB22: =VLOOKUP(A22,Jogos!A:BN,60,0) -> 72 | BC22: =VLOOKUP(A22,Jogos!A:BN,61,0) -> 27.605 | BD22: =VLOOKUP(A22,Jogos!A:BN,62,0) -> 0.5 | BE22: =VLOOKUP(A22,Jogos!A:BN,63,0) -> 2.07 | BF22: =VLOOKUP(A22,Jogos!A:BN,64,0) -> 24.755 | BG22: =VLOOKUP(A22,Jogos!A:BN,65,0) -> 42.805 | BH22: =VLOOKUP(A22,Jogos!A:BN,66,0) -> 28.715
A23: 1 | B23: Group A | C23: Group | D23: 45822 | E23: 0.83333333 | F23: =VLOOKUP(A23,Jogos!A:N,10,0) -> Evening | G23: Hard Rock Stadium | H23: =VLOOKUP(A23,Jogos!A:L,12,0) -> Open | I23: =VLOOKUP(G23,'Estádios e Cidades'!A:B,2,0) -> Miami Gardens - Flórida | J23: Inter Miami CF | K23: =VLOOKUP(J23,Equipes!A:F,6,0) -> Tropical | L23: =VLOOKUP(J23,Equipes!A:C,3,0) -> 16 | M23: =if(L23<3,"Final",IF(L23<5,"Semi-final",if(L23<9,"Quarter-final",if(L23<17,"Round of 16","Group")))) -> Round of 16 | N23: Al Ahly FC | O23: =VLOOKUP(N23,Equipes!A:C,3,0) -> 25 | P23: =if(O23<3,"Final",IF(O23<5,"Semi-final",if(O23<9,"Quarter-final",if(O23<17,"Round of 16","Group")))) -> Group | Q23: =L23-O23 -> -9 | R23: =VLOOKUP(J23,Equipes!A:B,2,0) -> InterMiami | S23: 21-InterMiami | T23: 21 | U23: Tadeo ALLENDE | V23: =VLOOKUP(U23,Jogadores!B:C,2,0) -> FW | W23: =VLOOKUP(U23,Jogadores!B:D,3,0) -> 26.452055 | X23: 0 | Y23: 81 | Z23: =VLOOKUP(A23,Jogos!A:L,3,0) -> 48 | AA23: =IF(X23<45,if(Y23>=45,Z23-X23,if(Y23<=Z23,Y23-X23,Z23)),0) -> 48 | AB23: =VLOOKUP(A23,Jogos!A:L,4,0) -> 53 | AC23: =IF(X23<45,if(Y23<=45,0,Y23-45),AB23+45-X23) -> 36 | AF23: =AE23+AC23+AA23 -> 84 | AG23: 8564 | AH23: 3417.3 | AI23: 3392.4 | AJ23: 1044.2 | AK23: 498.9 | AL23: 211.2 | AM23: 100 | AN23: 42 | AO23: 41.7 | AP23: =AG23/$AF23 -> 101.95238 | AQ23: =AH23/$AF23 -> 40.682143 | AR23: =AI23/$AF23 -> 40.385714 | AS23: =AQ23+AR23 -> 81.067857 | AT23: =AJ23/$AF23 -> 12.430952 | AU23: =AK23/$AF23 -> 5.9392857 | AV23: =AL23/$AF23 -> 2.5142857 | AW23: =(AK23+AL23)/AF23 -> 8.4535714 | AX23: =AM23/$AF23 -> 1.1904762 | AY23: =AN23/$AF23 -> 0.5 | AZ23: =VLOOKUP(A23,Jogos!A:BN,58,0) -> 28.26 | BA23: =VLOOKUP(A23,Jogos!A:BN,59,0) -> 22.895 | BB23: =VLOOKUP(A23,Jogos!A:BN,60,0) -> 72 | BC23: =VLOOKUP(A23,Jogos!A:BN,61,0) -> 27.605 | BD23: =VLOOKUP(A23,Jogos!A:BN,62,0) -> 0.5 | BE23: =VLOOKUP(A23,Jogos!A:BN,63,0) -> 2.07 | BF23: =VLOOKUP(A23,Jogos!A:BN,64,0) -> 24.755 | BG23: =VLOOKUP(A23,Jogos!A:BN,65,0) -> 42.805 | BH23: =VLOOKUP(A23,Jogos!A:BN,66,0) -> 28.715
A24: 1 | B24: Group A | C24: Group | D24: 45822 | E24: 0.83333333 | F24: =VLOOKUP(A24,Jogos!A:N,10,0) -> Evening | G24: Hard Rock Stadium | H24: =VLOOKUP(A24,Jogos!A:L,12,0) -> Open | I24: =VLOOKUP(G24,'Estádios e Cidades'!A:B,2,0) -> Miami Gardens - Flórida | J24: Inter Miami CF | K24: =VLOOKUP(J24,Equipes!A:F,6,0) -> Tropical | L24: =VLOOKUP(J24,Equipes!A:C,3,0) -> 16 | M24: =if(L24<3,"Final",IF(L24<5,"Semi-final",if(L24<9,"Quarter-final",if(L24<17,"Round of 16","Group")))) -> Round of 16 | N24: Al Ahly FC | O24: =VLOOKUP(N24,Equipes!A:C,3,0) -> 25 | P24: =if(O24<3,"Final",IF(O24<5,"Semi-final",if(O24<9,"Quarter-final",if(O24<17,"Round of 16","Group")))) -> Group | Q24: =L24-O24 -> -9 | R24: =VLOOKUP(J24,Equipes!A:B,2,0) -> InterMiami | S24: 32-InterMiami | T24: 32 | U24: Noah ALLEN | V24: =VLOOKUP(U24,Jogadores!B:C,2,0) -> DF | W24: =VLOOKUP(U24,Jogadores!B:D,3,0) -> 21.263014 | X24: 0 | Y24: =45+AB24 -> 98 | Z24: =VLOOKUP(A24,Jogos!A:L,3,0) -> 48 | AA24: =IF(X24<45,if(Y24>=45,Z24-X24,if(Y24<=Z24,Y24-X24,Z24)),0) -> 48 | AB24: =VLOOKUP(A24,Jogos!A:L,4,0) -> 53 | AC24: =IF(X24<45,if(Y24<=45,0,Y24-45),AB24+45-X24) -> 53 | AF24: =AE24+AC24+AA24 -> 101 | AG24: 10636.8 | AH24: 3894.3 | AI24: 4409.8 | AJ24: 1268.3 | AK24: 651.4 | AL24: 413 | AM24: 109 | AN24: 58 | AO24: 41.1 | AP24: =AG24/$AF24 -> 105.31485 | AQ24: =AH24/$AF24 -> 38.557426 | AR24: =AI24/$AF24 -> 43.661386 | AS24: =AQ24+AR24 -> 82.218812 | AT24: =AJ24/$AF24 -> 12.557426 | AU24: =AK24/$AF24 -> 6.4495049 | AV24: =AL24/$AF24 -> 4.0891089 | AW24: =(AK24+AL24)/AF24 -> 10.538614 | AX24: =AM24/$AF24 -> 1.0792079 | AY24: =AN24/$AF24 -> 0.57425743 | AZ24: =VLOOKUP(A24,Jogos!A:BN,58,0) -> 28.26 | BA24: =VLOOKUP(A24,Jogos!A:BN,59,0) -> 22.895 | BB24: =VLOOKUP(A24,Jogos!A:BN,60,0) -> 72 | BC24: =VLOOKUP(A24,Jogos!A:BN,61,0) -> 27.605 | BD24: =VLOOKUP(A24,Jogos!A:BN,62,0) -> 0.5 | BE24: =VLOOKUP(A24,Jogos!A:BN,63,0) -> 2.07 | BF24: =VLOOKUP(A24,Jogos!A:BN,64,0) -> 24.755 | BG24: =VLOOKUP(A24,Jogos!A:BN,65,0) -> 42.805 | BH24: =VLOOKUP(A24,Jogos!A:BN,66,0) -> 28.715
A25: 1 | B25: Group A | C25: Group | D25: 45822 | E25: 0.83333333 | F25: =VLOOKUP(A25,Jogos!A:N,10,0) -> Evening | G25: Hard Rock Stadium | H25: =VLOOKUP(A25,Jogos!A:L,12,0) -> Open | I25: =VLOOKUP(G25,'Estádios e Cidades'!A:B,2,0) -> Miami Gardens - Flórida | J25: Inter Miami CF | K25: =VLOOKUP(J25,Equipes!A:F,6,0) -> Tropical | L25: =VLOOKUP(J25,Equipes!A:C,3,0) -> 16 | M25: =if(L25<3,"Final",IF(L25<5,"Semi-final",if(L25<9,"Quarter-final",if(L25<17,"Round of 16","Group")))) -> Round of 16 | N25: Al Ahly FC | O25: =VLOOKUP(N25,Equipes!A:C,3,0) -> 25 | P25: =if(O25<3,"Final",IF(O25<5,"Semi-final",if(O25<9,"Quarter-final",if(O25<17,"Round of 16","Group")))) -> Group | Q25: =L25-O25 -> -9 | R25: =VLOOKUP(J25,Equipes!A:B,2,0) -> InterMiami | S25: 37-InterMiami | T25: 37 | U25: Maximiliano FALCON | V25: =VLOOKUP(U25,Jogadores!B:C,2,0) -> DF | W25: =VLOOKUP(U25,Jogadores!B:D,3,0) -> 28.260274 | X25: 0 | Y25: =45+AB25 -> 98 | Z25: =VLOOKUP(A25,Jogos!A:L,3,0) -> 48 | AA25: =IF(X25<45,if(Y25>=45,Z25-X25,if(Y25<=Z25,Y25-X25,Z25)),0) -> 48 | AB25: =VLOOKUP(A25,Jogos!A:L,4,0) -> 53 | AC25: =IF(X25<45,if(Y25<=45,0,Y25-45),AB25+45-X25) -> 53 | AF25: =AE25+AC25+AA25 -> 101 | AG25: 9395.7 | AH25: 4247.6 | AI25: 3669.7 | AJ25: 794.8 | AK25: 445.9 | AL25: 237.7 | AM25: 67 | AN25: 42 | AO25: 41.9 | AP25: =AG25/$AF25 -> 93.026733 | AQ25: =AH25/$AF25 -> 42.055446 | AR25: =AI25/$AF25 -> 36.333663 | AS25: =AQ25+AR25 -> 78.389109 | AT25: =AJ25/$AF25 -> 7.8693069 | AU25: =AK25/$AF25 -> 4.4148515 | AV25: =AL25/$AF25 -> 2.3534653 | AW25: =(AK25+AL25)/AF25 -> 6.7683168 | AX25: =AM25/$AF25 -> 0.66336634 | AY25: =AN25/$AF25 -> 0.41584158 | AZ25: =VLOOKUP(A25,Jogos!A:BN,58,0) -> 28.26 | BA25: =VLOOKUP(A25,Jogos!A:BN,59,0) -> 22.895 | BB25: =VLOOKUP(A25,Jogos!A:BN,60,0) -> 72 | BC25: =VLOOKUP(A25,Jogos!A:BN,61,0) -> 27.605 | BD25: =VLOOKUP(A25,Jogos!A:BN,62,0) -> 0.5 | BE25: =VLOOKUP(A25,Jogos!A:BN,63,0) -> 2.07 | BF25: =VLOOKUP(A25,Jogos!A:BN,64,0) -> 24.755 | BG25: =VLOOKUP(A25,Jogos!A:BN,65,0) -> 42.805 | BH25: =VLOOKUP(A25,Jogos!A:BN,66,0) -> 28.715
A26: 1 | B26: Group A | C26: Group | D26: 45822 | E26: 0.83333333 | F26: =VLOOKUP(A26,Jogos!A:N,10,0) -> Evening | G26: Hard Rock Stadium | H26: =VLOOKUP(A26,Jogos!A:L,12,0) -> Open | I26: =VLOOKUP(G26,'Estádios e Cidades'!A:B,2,0) -> Miami Gardens - Flórida | J26: Inter Miami CF | K26: =VLOOKUP(J26,Equipes!A:F,6,0) -> Tropical | L26: =VLOOKUP(J26,Equipes!A:C,3,0) -> 16 | M26: =if(L26<3,"Final",IF(L26<5,"Semi-final",if(L26<9,"Quarter-final",if(L26<17,"Round of 16","Group")))) -> Round of 16 | N26: Al Ahly FC | O26: =VLOOKUP(N26,Equipes!A:C,3,0) -> 25 | P26: =if(O26<3,"Final",IF(O26<5,"Semi-final",if(O26<9,"Quarter-final",if(O26<17,"Round of 16","Group")))) -> Group | Q26: =L26-O26 -> -9 | R26: =VLOOKUP(J26,Equipes!A:B,2,0) -> InterMiami | S26: 55-InterMiami | T26: 55 | U26: Federico REDONDO | V26: =VLOOKUP(U26,Jogadores!B:C,2,0) -> MF | W26: =VLOOKUP(U26,Jogadores!B:D,3,0) -> 22.539726 | X26: 0 | Y26: =45+AB26 -> 98 | Z26: =VLOOKUP(A26,Jogos!A:L,3,0) -> 48 | AA26: =IF(X26<45,if(Y26>=45,Z26-X26,if(Y26<=Z26,Y26-X26,Z26)),0) -> 48 | AB26: =VLOOKUP(A26,Jogos!A:L,4,0) -> 53 | AC26: =IF(X26<45,if(Y26<=45,0,Y26-45),AB26+45-X26) -> 53 | AF26: =AE26+AC26+AA26 -> 101 | AG26: 9881.1 | AH26: 4120.3 | AI26: 4159.6 | AJ26: 1016.5 | AK26: 447.9 | AL26: 136.9 | AM26: 88 | AN26: 34 | AO26: 35 | AP26: =AG26/$AF26 -> 97.832673 | AQ26: =AH26/$AF26 -> 40.795049 | AR26: =AI26/$AF26 -> 41.184158 | AS26: =AQ26+AR26 -> 81.979208 | AT26: =AJ26/$AF26 -> 10.064356 | AU26: =AK26/$AF26 -> 4.4346535 | AV26: =AL26/$AF26 -> 1.3554455 | AW26: =(AK26+AL26)/AF26 -> 5.790099 | AX26: =AM26/$AF26 -> 0.87128713 | AY26: =AN26/$AF26 -> 0.33663366 | AZ26: =VLOOKUP(A26,Jogos!A:BN,58,0) -> 28.26 | BA26: =VLOOKUP(A26,Jogos!A:BN,59,0) -> 22.895 | BB26: =VLOOKUP(A26,Jogos!A:BN,60,0) -> 72 | BC26: =VLOOKUP(A26,Jogos!A:BN,61,0) -> 27.605 | BD26: =VLOOKUP(A26,Jogos!A:BN,62,0) -> 0.5 | BE26: =VLOOKUP(A26,Jogos!A:BN,63,0) -> 2.07 | BF26: =VLOOKUP(A26,Jogos!A:BN,64,0) -> 24.755 | BG26: =VLOOKUP(A26,Jogos!A:BN,65,0) -> 42.805 | BH26: =VLOOKUP(A26,Jogos!A:BN,66,0) -> 28.715
A27: 1 | B27: Group A | C27: Group | D27: 45822 | E27: 0.83333333 | F27: =VLOOKUP(A27,Jogos!A:N,10,0) -> Evening | G27: Hard Rock Stadium | H27: =VLOOKUP(A27,Jogos!A:L,12,0) -> Open | I27: =VLOOKUP(G27,'Estádios e Cidades'!A:B,2,0) -> Miami Gardens - Flórida | J27: Inter Miami CF | K27: =VLOOKUP(J27,Equipes!A:F,6,0) -> Tropical | L27: =VLOOKUP(J27,Equipes!A:C,3,0) -> 16 | M27: =if(L27<3,"Final",IF(L27<5,"Semi-final",if(L27<9,"Quarter-final",if(L27<17,"Round of 16","Group")))) -> Round of 16 | N27: Al Ahly FC | O27: =VLOOKUP(N27,Equipes!A:C,3,0) -> 25 | P27: =if(O27<3,"Final",IF(O27<5,"Semi-final",if(O27<9,"Quarter-final",if(O27<17,"Round of 16","Group")))) -> Group | Q27: =L27-O27 -> -9 | R27: =VLOOKUP(J27,Equipes!A:B,2,0) -> InterMiami | S27: 7-InterMiami | T27: 7 | U27: Fafa PICAULT | V27: =VLOOKUP(U27,Jogadores!B:C,2,0) -> FW | W27: =VLOOKUP(U27,Jogadores!B:D,3,0) -> 34.449315 | X27: 81 | Y27: =45+AB27 -> 98 | Z27: =VLOOKUP(A27,Jogos!A:L,3,0) -> 48 | AA27: =IF(X27<45,if(Y27>=45,Z27-X27,if(Y27<=Z27,Y27-X27,Z27)),0) -> 0 | AB27: =VLOOKUP(A27,Jogos!A:L,4,0) -> 53 | AC27: =IF(X27<45,if(Y27<=45,0,Y27-45),AB27+45-X27) -> 17 | AF27: =AE27+AC27+AA27 -> 17 | AG27: 1934.3 | AH27: 608.7 | AI27: 830.9 | AJ27: 247.3 | AK27: 162.7 | AL27: 84.7 | AM27: 20 | AN27: 13 | AO27: 31.4 | AP27: =AG27/$AF27 -> 113.78235 | AQ27: =AH27/$AF27 -> 35.805882 | AR27: =AI27/$AF27 -> 48.876471 | AS27: =AQ27+AR27 -> 84.682353 | AT27: =AJ27/$AF27 -> 14.547059 | AU27: =AK27/$AF27 -> 9.5705882 | AV27: =AL27/$AF27 -> 4.9823529 | AW27: =(AK27+AL27)/AF27 -> 14.552941 | AX27: =AM27/$AF27 -> 1.1764706 | AY27: =AN27/$AF27 -> 0.76470588 | AZ27: =VLOOKUP(A27,Jogos!A:BN,58,0) -> 28.26 | BA27: =VLOOKUP(A27,Jogos!A:BN,59,0) -> 22.895 | BB27: =VLOOKUP(A27,Jogos!A:BN,60,0) -> 72 | BC27: =VLOOKUP(A27,Jogos!A:BN,61,0) -> 27.605 | BD27: =VLOOKUP(A27,Jogos!A:BN,62,0) -> 0.5 | BE27: =VLOOKUP(A27,Jogos!A:BN,63,0) -> 2.07 | BF27: =VLOOKUP(A27,Jogos!A:BN,64,0) -> 24.755 | BG27: =VLOOKUP(A27,Jogos!A:BN,65,0) -> 42.805 | BH27: =VLOOKUP(A27,Jogos!A:BN,66,0) -> 28.715
A28: 1 | B28: Group A | C28: Group | D28: 45822 | E28: 0.83333333 | F28: =VLOOKUP(A28,Jogos!A:N,10,0) -> Evening | G28: Hard Rock Stadium | H28: =VLOOKUP(A28,Jogos!A:L,12,0) -> Open | I28: =VLOOKUP(G28,'Estádios e Cidades'!A:B,2,0) -> Miami Gardens - Flórida | J28: Inter Miami CF | K28: =VLOOKUP(J28,Equipes!A:F,6,0) -> Tropical | L28: =VLOOKUP(J28,Equipes!A:C,3,0) -> 16 | M28: =if(L28<3,"Final",IF(L28<5,"Semi-final",if(L28<9,"Quarter-final",if(L28<17,"Round of 16","Group")))) -> Round of 16 | N28: Al Ahly FC | O28: =VLOOKUP(N28,Equipes!A:C,3,0) -> 25 | P28: =if(O28<3,"Final",IF(O28<5,"Semi-final",if(O28<9,"Quarter-final",if(O28<17,"Round of 16","Group")))) -> Group | Q28: =L28-O28 -> -9 | R28: =VLOOKUP(J28,Equipes!A:B,2,0) -> InterMiami | S28: 30-InterMiami | T28: 30 | U28: Benjamin CREMASCHI | V28: =VLOOKUP(U28,Jogadores!B:C,2,0) -> MF | W28: =VLOOKUP(U28,Jogadores!B:D,3,0) -> 20.419178 | X28: 73 | Y28: =45+AB28 -> 98 | Z28: =VLOOKUP(A28,Jogos!A:L,3,0) -> 48 | AA28: =IF(X28<45,if(Y28>=45,Z28-X28,if(Y28<=Z28,Y28-X28,Z28)),0) -> 0 | AB28: =VLOOKUP(A28,Jogos!A:L,4,0) -> 53 | AC28: =IF(X28<45,if(Y28<=45,0,Y28-45),AB28+45-X28) -> 25 | AF28: =AE28+AC28+AA28 -> 25 | AG28: 3071.4 | AH28: 914.9 | AI28: 1258.3 | AJ28: 609.3 | AK28: 193.4 | AL28: 95.5 | AM28: 42 | AN28: 19 | AO28: 30.2 | AP28: =AG28/$AF28 -> 122.856 | AQ28: =AH28/$AF28 -> 36.596 | AR28: =AI28/$AF28 -> 50.332 | AS28: =AQ28+AR28 -> 86.928 | AT28: =AJ28/$AF28 -> 24.372 | AU28: =AK28/$AF28 -> 7.736 | AV28: =AL28/$AF28 -> 3.82 | AW28: =(AK28+AL28)/AF28 -> 11.556 | AX28: =AM28/$AF28 -> 1.68 | AY28: =AN28/$AF28 -> 0.76 | AZ28: =VLOOKUP(A28,Jogos!A:BN,58,0) -> 28.26 | BA28: =VLOOKUP(A28,Jogos!A:BN,59,0) -> 22.895 | BB28: =VLOOKUP(A28,Jogos!A:BN,60,0) -> 72 | BC28: =VLOOKUP(A28,Jogos!A:BN,61,0) -> 27.605 | BD28: =VLOOKUP(A28,Jogos!A:BN,62,0) -> 0.5 | BE28: =VLOOKUP(A28,Jogos!A:BN,63,0) -> 2.07 | BF28: =VLOOKUP(A28,Jogos!A:BN,64,0) -> 24.755 | BG28: =VLOOKUP(A28,Jogos!A:BN,65,0) -> 42.805 | BH28: =VLOOKUP(A28,Jogos!A:BN,66,0) -> 28.715
A29: 1 | B29: Group A | C29: Group | D29: 45822 | E29: 0.83333333 | F29: =VLOOKUP(A29,Jogos!A:N,10,0) -> Evening | G29: Hard Rock Stadium | H29: =VLOOKUP(A29,Jogos!A:L,12,0) -> Open | I29: =VLOOKUP(G29,'Estádios e Cidades'!A:B,2,0) -> Miami Gardens - Flórida | J29: Inter Miami CF | K29: =VLOOKUP(J29,Equipes!A:F,6,0) -> Tropical | L29: =VLOOKUP(J29,Equipes!A:C,3,0) -> 16 | M29: =if(L29<3,"Final",IF(L29<5,"Semi-final",if(L29<9,"Quarter-final",if(L29<17,"Round of 16","Group")))) -> Round of 16 | N29: Al Ahly FC | O29: =VLOOKUP(N29,Equipes!A:C,3,0) -> 25 | P29: =if(O29<3,"Final",IF(O29<5,"Semi-final",if(O29<9,"Quarter-final",if(O29<17,"Round of 16","Group")))) -> Group | Q29: =L29-O29 -> -9 | R29: =VLOOKUP(J29,Equipes!A:B,2,0) -> InterMiami | S29: 57-InterMiami | T29: 57 | U29: Marcelo WEIGANDT | V29: =VLOOKUP(U29,Jogadores!B:C,2,0) -> DF | W29: =VLOOKUP(U29,Jogadores!B:D,3,0) -> 25.561644 | X29: 45 | Y29: =45+AB29 -> 98 | Z29: =VLOOKUP(A29,Jogos!A:L,3,0) -> 48 | AA29: =IF(X29<45,if(Y29>=45,Z29-X29,if(Y29<=Z29,Y29-X29,Z29)),0) -> 0 | AB29: =VLOOKUP(A29,Jogos!A:L,4,0) -> 53 | AC29: =IF(X29<45,if(Y29<=45,0,Y29-45),AB29+45-X29) -> 53 | AF29: =AE29+AC29+AA29 -> 53 | AG29: 5297.9 | AH29: 2102.2 | AI29: 1946.6 | AJ29: 705.4 | AK29: 310.5 | AL29: 233.2 | AM29: 61 | AN29: 33 | AO29: 32.8 | AP29: =AG29/$AF29 -> 99.960377 | AQ29: =AH29/$AF29 -> 39.664151 | AR29: =AI29/$AF29 -> 36.728302 | AS29: =AQ29+AR29 -> 76.392453 | AT29: =AJ29/$AF29 -> 13.309434 | AU29: =AK29/$AF29 -> 5.8584906 | AV29: =AL29/$AF29 -> 4.4 | AW29: =(AK29+AL29)/AF29 -> 10.258491 | AX29: =AM29/$AF29 -> 1.1509434 | AY29: =AN29/$AF29 -> 0.62264151 | AZ29: =VLOOKUP(A29,Jogos!A:BN,58,0) -> 28.26 | BA29: =VLOOKUP(A29,Jogos!A:BN,59,0) -> 22.895 | BB29: =VLOOKUP(A29,Jogos!A:BN,60,0) -> 72 | BC29: =VLOOKUP(A29,Jogos!A:BN,61,0) -> 27.605 | BD29: =VLOOKUP(A29,Jogos!A:BN,62,0) -> 0.5 | BE29: =VLOOKUP(A29,Jogos!A:BN,63,0) -> 2.07 | BF29: =VLOOKUP(A29,Jogos!A:BN,64,0) -> 24.755 | BG29: =VLOOKUP(A29,Jogos!A:BN,65,0) -> 42.805 | BH29: =VLOOKUP(A29,Jogos!A:BN,66,0) -> 28.715
A30: 2 | B30: Group C | C30: Group | D30: 45823 | E30: 0.5 | F30: =VLOOKUP(A30,Jogos!A:N,10,0) -> Afternoon | G30: TQL Stadium | H30: =VLOOKUP(A30,Jogos!A:L,12,0) -> Open | I30: =VLOOKUP(G30,'Estádios e Cidades'!A:B,2,0) -> Cincinnati | J30: FC Bayern Munchen | K30: =VLOOKUP(J30,Equipes!A:F,6,0) -> Temperate | L30: =VLOOKUP(J30,Equipes!A:C,3,0) -> 6 | M30: =if(L30<3,"Final",IF(L30<5,"Semi-final",if(L30<9,"Quarter-final",if(L30<17,"Round of 16","Group")))) -> Quarter-final | N30: Auckland City FC | O30: =VLOOKUP(N30,Equipes!A:C,3,0) -> 27 | P30: =if(O30<3,"Final",IF(O30<5,"Semi-final",if(O30<9,"Quarter-final",if(O30<17,"Round of 16","Group")))) -> Group | Q30: =L30-O30 -> -21 | R30: =VLOOKUP(J30,Equipes!A:B,2,0) -> Bayern | S30: 4-Bayern | T30: 4 | U30: Jonathan TAH | V30: =VLOOKUP(U30,Jogadores!B:C,2,0) -> DF | W30: =VLOOKUP(U30,Jogadores!B:D,3,0) -> 29.479452 | X30: 0 | Y30: =45+AB30 -> 95 | Z30: =VLOOKUP(A30,Jogos!A:L,3,0) -> 49 | AA30: =IF(X30<45,if(Y30>=45,Z30-X30,if(Y30<=Z30,Y30-X30,Z30)),0) -> 49 | AB30: =VLOOKUP(A30,Jogos!A:L,4,0) -> 50 | AC30: =IF(X30<45,if(Y30<=45,0,Y30-45),AB30+45-X30) -> 50 | AF30: =AE30+AC30+AA30 -> 99 | AG30: 10950.9 | AH30: 4450.3 | AI30: 4702.8 | AJ30: 1232.4 | AK30: 449.3 | AL30: 116.2 | AM30: 120 | AN30: 34 | AO30: 32 | AP30: =AG30/$AF30 -> 110.61515 | AQ30: =AH30/$AF30 -> 44.952525 | AR30: =AI30/$AF30 -> 47.50303 | AS30: =AQ30+AR30 -> 92.455556 | AT30: =AJ30/$AF30 -> 12.448485 | AU30: =AK30/$AF30 -> 4.5383838 | AV30: =AL30/$AF30 -> 1.1737374 | AW30: =(AK30+AL30)/AF30 -> 5.7121212 | AX30: =AM30/$AF30 -> 1.2121212 | AY30: =AN30/$AF30 -> 0.34343434 | AZ30: =VLOOKUP(A30,Jogos!A:BN,58,0) -> 26.09 | BA30: =VLOOKUP(A30,Jogos!A:BN,59,0) -> 21.3 | BB30: =VLOOKUP(A30,Jogos!A:BN,60,0) -> 74.5 | BC30: =VLOOKUP(A30,Jogos!A:BN,61,0) -> 24.475 | BD30: =VLOOKUP(A30,Jogos!A:BN,62,0) -> 547.2 | BE30: =VLOOKUP(A30,Jogos!A:BN,63,0) -> 1.025 | BF30: =VLOOKUP(A30,Jogos!A:BN,64,0) -> 23.575 | BG30: =VLOOKUP(A30,Jogos!A:BN,65,0) -> 41.075 | BH30: =VLOOKUP(A30,Jogos!A:BN,66,0) -> 27.33
